<?xml version="1.0" ?>
<!-- =================================================================================== -->
<!-- |    This document was autogenerated by xacro from /home/tom/catkin_ws/src/robot_project/marimbabot_description/urdf/marimbabot_ur5.urdf.xacro | -->
<!-- |    EDITING THIS FILE BY HAND IS NOT RECOMMENDED                                 | -->
<!-- =================================================================================== -->
<robot name="marimbabot_ur5">
    <material name="black">
        <color rgba="0.0 0.0 0.0 1.0" />
    </material>
    <material name="white">
        <color rgba="1 1 1 1" />
    </material>
    <material name="brown">
        <color rgba="0.87 0.72 0.53 1" />
    </material>
    <material name="lightgray">
        <color rgba="0.6 0.6 0.6 1" />
    </material>
    <link name="floor">
        <inertial>
            <origin xyz="2.5 2.5 0" rpy="0 0 0" />
            <mass value="2000" />
            <inertia ixx="1" ixy="0" ixz="0" iyy="1" iyz="0" izz="1" />
        </inertial>
        <visual>
            <material name="black" />
            <origin xyz="2.5 2.4175 0" />
            <geometry>
                <box size="5.0 5.165 0.001" />
            </geometry>
        </visual>
        <collision>
            <origin xyz="2.5 2.4175 0" />
            <geometry>
                <box size="5.0 5.165 0.001" />
            </geometry>
        </collision>
    </link>
    <gazebo reference="floor">
        <material>Gazebo/Blue</material>
        <turnGravityOff>false</turnGravityOff>
        <selfCollide>true</selfCollide>
        <!-- kp: stiffness kd: damping mu1, mu2: friction -->
        <mu1>100.0</mu1>
        <mu2>100.0</mu2>
        <kp>1000000.0</kp>
        <kd>1.0</kd>
        <plugin name="gazebo_ros_control">
            <robotNamespace>/</robotNamespace>
        </plugin>
    </gazebo>
    <link name="wall">
        <inertial>
            <origin xyz="-0.06 2.5 1.5" rpy="0 0 0" />
            <mass value="2000" />
            <inertia ixx="1" ixy="0" ixz="0" iyy="1" iyz="0" izz="1" />
        </inertial>
        <visual>
            <material name="wall_mat">
                <color rgba="1.0 1.0 1.0 0.4" />
            </material>
            <origin xyz="-0.06 2.5 1.5" />
            <geometry>
                <box size="0.12 5.0 3.0" />
            </geometry>
        </visual>
        <collision>
            <origin xyz="-0.06 2.5 1.5" />
            <geometry>
                <box size="0.12 5.0 3.0" />
            </geometry>
        </collision>
    </link>
    <gazebo reference="wall">
        <material>Gazebo/Blue</material>
        <turnGravityOff>false</turnGravityOff>
        <selfCollide>true</selfCollide>
        <!-- kp: stiffness kd: damping mu1, mu2: friction -->
        <mu1>100.0</mu1>
        <mu2>100.0</mu2>
        <kp>1000000.0</kp>
        <kd>1.0</kd>
    </gazebo>
    <!-- frame of the ur5 mount plate -->
    <link name="ur5_mount_plate" />
    <!-- tilted ur5 mount - the meshes are not centered at mount point so they are adjusted to fit to the frame -->
    <link name="ur5_mount">
        <visual>
            <material name="lightgray" />
            <origin xyz="-0.0245 -0.09 -0.28" />
            <geometry>
                <mesh filename="package://tams_ur5_setup_description/meshes/ur5_mount_binary_v3.stl" scale="0.001 0.001 0.001" />
            </geometry>
        </visual>
        <collision>
            <origin xyz="-0.0245 -0.09 -0.28" />
            <geometry>
                <mesh filename="package://tams_ur5_setup_description/meshes/ur5_mount_binary_v3.stl" scale="0.001 0.001 0.001" />
            </geometry>
        </collision>
        <inertial>
            <mass value="0.1" />
            <origin xyz="0 0 0" rpy="0 0 0" />
            <inertia ixx="0.03" iyy="0.03" izz="0.03" ixy="0.0" ixz="0.0" iyz="0.0" />
        </inertial>
    </link>
    <link name="side_wall">
        <inertial>
            <origin xyz="0 0 0" rpy="0 0 0" />
            <mass value="2000" />
            <inertia ixx="1" ixy="0" ixz="0" iyy="1" iyz="0" izz="1" />
        </inertial>
        <visual>
            <material name="side_wall_mat">
                <color rgba="1.0 1.0 1.0 0.4" />
            </material>
            <origin xyz="0 0 0" />
            <geometry>
                <box size="5.0 0.12 3.0" />
            </geometry>
        </visual>
        <collision>
            <origin xyz="0 0 0.0" />
            <geometry>
                <box size="5.0 0.12 3.0" />
            </geometry>
        </collision>
    </link>
    <gazebo reference="side_wall">
        <material>Gazebo/Blue</material>
        <turnGravityOff>false</turnGravityOff>
        <selfCollide>true</selfCollide>
        <!-- kp: stiffness kd: damping mu1, mu2: friction -->
        <mu1>100.0</mu1>
        <mu2>100.0</mu2>
        <kp>1000000.0</kp>
        <kd>1.0</kd>
    </gazebo>
    <link name="small_wall">
        <inertial>
            <origin xyz="0 0 0" rpy="0 0 0" />
            <mass value="2000" />
            <inertia ixx="1" ixy="0" ixz="0" iyy="1" iyz="0" izz="1" />
        </inertial>
        <visual>
            <material name="small_wall_mat">
                <color rgba="1.0 1.0 1.0 0.4" />
            </material>
            <origin xyz="0 0 0" />
            <geometry>
                <box size="0.19 0.165 3.0" />
            </geometry>
        </visual>
        <collision>
            <origin xyz="0 0 0.0" />
            <geometry>
                <!-- the collision model is 7cm wider due to security reasons -->
                <box size="0.33 0.305 3.0" />
            </geometry>
        </collision>
    </link>
    <gazebo reference="small_wall">
        <material>Gazebo/Blue</material>
        <turnGravityOff>false</turnGravityOff>
        <selfCollide>true</selfCollide>
        <!-- kp: stiffness kd: damping mu1, mu2: friction -->
        <mu1>100.0</mu1>
        <mu2>100.0</mu2>
        <kp>1000000.0</kp>
        <kd>1.0</kd>
    </gazebo>
    <link name="cable_duct">
        <inertial>
            <origin xyz="0 0 0" rpy="0 0 0" />
            <mass value="2000" />
            <inertia ixx="1" ixy="0" ixz="0" iyy="1" iyz="0" izz="1" />
        </inertial>
        <visual>
            <material name="cable_duct_mat">
                <color rgba="0.7 0.7 0.7 0.4" />
            </material>
            <origin xyz="0 0 0" />
            <geometry>
                <box size="0.13 0.06 3.0" />
            </geometry>
        </visual>
        <collision>
            <origin xyz="0 0 0" />
            <geometry>
                <!-- the collision model is 7cm wider then the actual duct, because of an unmodelled ethernet port -->
                <box size="0.27 0.2 3.0" />
            </geometry>
        </collision>
    </link>
    <gazebo reference="cable_duct">
        <material>Gazebo/Blue</material>
        <turnGravityOff>false</turnGravityOff>
        <selfCollide>true</selfCollide>
        <!-- kp: stiffness kd: damping mu1, mu2: friction -->
        <mu1>100.0</mu1>
        <mu2>100.0</mu2>
        <kp>1000000.0</kp>
        <kd>1.0</kd>
    </gazebo>
    <link name="shelf">
        <inertial>
            <origin xyz="1.7 0 0" rpy="0 0 0" />
            <mass value="60" />
            <inertia ixx="1" ixy="0" ixz="0" iyy="1" iyz="0" izz="1" />
        </inertial>
        <visual>
            <material name="shelf_mat">
                <color rgba="0.7 0.7 0.7 0.4" />
            </material>
            <origin xyz="0 1.7 0" />
            <geometry>
                <box size="0.4 2 2.5" />
            </geometry>
        </visual>
        <collision>
            <origin xyz="0 1.7 0" />
            <geometry>
                <!-- the collision model is 7cm wider due to security reasons -->
                <box size="0.54 2.14 2.5" />
            </geometry>
        </collision>
    </link>
    <gazebo reference="shelf">
        <material>Gazebo/Orange</material>
        <turnGravityOff>false</turnGravityOff>
        <selfCollide>true</selfCollide>
        <!-- kp: stiffness kd: damping mu1, mu2: friction -->
        <mu1>100.0</mu1>
        <mu2>100.0</mu2>
        <kp>1000000.0</kp>
        <kd>1.0</kd>
    </gazebo>
    <link name="april_tag_ur5">
        <inertial>
            <origin xyz="0 0 0" rpy="0 0 0" />
            <mass value="2000" />
            <inertia ixx="1" ixy="0" ixz="0" iyy="1" iyz="0" izz="1" />
        </inertial>
        <visual>
            <material name="lightgray" />
            <origin xyz="0 0 0" />
            <geometry>
                <box size="0.166 0.166 0.01" />
            </geometry>
        </visual>
        <collision>
            <origin xyz="0 0 0.0" />
            <geometry>
                <box size="0.166 0.166 0.01" />
            </geometry>
        </collision>
    </link>
    <gazebo reference="april_tag_ur5">
        <material>Gazebo/Blue</material>
        <turnGravityOff>false</turnGravityOff>
        <selfCollide>true</selfCollide>
        <mu1>100.0</mu1>
        <mu2>100.0</mu2>
        <kp>1000000.0</kp>
        <kd>1.0</kd>
    </gazebo>
    <link name="clock">
        <inertial>
            <origin xyz="0 0 0" rpy="0 0 0" />
            <mass value="2000" />
            <inertia ixx="1" ixy="0" ixz="0" iyy="1" iyz="0" izz="1" />
        </inertial>
        <visual>
            <material name="clock_mat">
                <color rgba="0.7 0.7 0.7 0.4" />
            </material>
            <origin xyz="0 0 0" />
            <geometry>
                <cylinder length="0.06" radius="0.14" />
            </geometry>
        </visual>
        <collision>
            <origin xyz="0 0 0.0" />
            <geometry>
                <cylinder length="0.06" radius="0.14" />
            </geometry>
        </collision>
    </link>
    <link name="turtlebot" />
    <link name="turtlebot_holder" />
    <joint name="floor_wall_joint" type="fixed">
        <parent link="floor" />
        <child link="wall" />
        <!-- The actual wall in the lab is slightly tilted, the rotation compensates approx 1 deg -->
        <origin rpy="0 0 0" xyz="0 0 0" />
        <!--<origin xyz="0 0 0" rpy="0 -0.017 0" />-->
    </joint>
    <joint name="wall_mount_plate_joint" type="fixed">
        <parent link="wall" />
        <child link="ur5_mount_plate" />
        <origin rpy="0 0 0" xyz="0.0 0.7245 1.05" />
    </joint>
    <joint name="wall_mount_joint" type="fixed">
        <parent link="ur5_mount_plate" />
        <child link="ur5_mount" />
        <origin rpy="0 0 3.141592653589793" xyz="0.2255 -0.025 0.032" />
    </joint>
    <joint name="side_wall_joint" type="fixed">
        <parent link="floor" />
        <child link="side_wall" />
        <!--<origin xyz="2.5 -0.06 1.5" rpy="0 0 0" />-->
        <origin rpy="0 0 0" xyz="2.5 -0.225 1.5" />
    </joint>
    <joint name="small_wall_joint" type="fixed">
        <parent link="floor" />
        <child link="small_wall" />
        <!--<origin xyz="2.5 -0.06 1.5" rpy="0 0 0" />-->
        <origin rpy="0 0 0" xyz="0.07 -0.0825 1.5" />
    </joint>
    <joint name="cable_duct_joint" type="fixed">
        <parent link="floor" />
        <child link="cable_duct" />
        <origin rpy="0 0 0" xyz="0.475 -0.135 1.5" />
    </joint>
    <joint name="shelf_joint" type="fixed">
        <parent link="floor" />
        <child link="shelf" />
        <!-- actual shelf is a little smaller -->
        <origin rpy="0 0 0" xyz="0.2 1 1.25" />
    </joint>
    <joint name="apriltag_ur5_joint" type="fixed">
        <parent link="wall" />
        <child link="april_tag_ur5" />
        <!-- <origin xyz="-0.015 0.75 1.494" rpy="${-pi/2-0.05} 0.0 ${-pi/2}" /> -->
        <!-- with rotation correction -->
        <origin rpy="-1.5707963267948966 0.0 -1.5557963267948967" xyz="-0.009 0.74 1.505" />
        <!-- offset relative to the tilted wall -->
    </joint>
    <joint name="clock_joint" type="fixed">
        <parent link="wall" />
        <child link="clock" />
        <origin rpy="-1.5707963267948966 0.0 -1.5707963267948966" xyz="0.03 0.82 1.93" />
        <!-- offset relative to the tilted wall -->
    </joint>
    <joint name="turtlebot_joint" type="fixed">
        <parent link="world" />
        <child link="turtlebot" />
        <origin rpy="0.0 0.0 0.0" xyz="0.26 1.31 0.0" />
    </joint>
    <joint name="turtlebot_holder_joint" type="fixed">
        <parent link="turtlebot" />
        <child link="turtlebot_holder" />
        <origin rpy="0.0 0.0 0.0" xyz="0.04 0.0 0.41" />
    </joint>
    <!-- fnh: copied from tams_ur5_description/urdf/ur5.urdf.xacro -->
    <!-- we don't want these
  <xacro:include filename="$(find tams_ur5_setup_description)/urdf/upstream/ur.transmission.xacro" />
  <xacro:include filename="$(find tams_ur5_setup_description)/urdf/upstream/ur.gazebo.xacro" />
  -->
    <!-- measured from model -->
    <!--property name="shoulder_height" value="0.089159" /-->
    <!--property name="shoulder_offset" value="0.13585" /-->
    <!-- shoulder_offset - elbow_offset + wrist_1_length = 0.10915 -->
    <!--property name="upper_arm_length" value="0.42500" /-->
    <!--property name="elbow_offset" value="0.1197" /-->
    <!-- CAD measured -->
    <!--property name="forearm_length" value="0.39225" /-->
    <!--property name="wrist_1_length" value="0.093" /-->
    <!-- CAD measured -->
    <!--property name="wrist_2_length" value="0.09465" /-->
    <!-- In CAD this distance is 0.930, but in the spec it is 0.09465 -->
    <!--property name="wrist_3_length" value="0.0823" /-->
    <!-- manually measured -->
    <!-- idea and easy_box borrowed from B21.xacro, 
     <url>http://ros.org/wiki/b21_description</url>, BSD license 

  (C) 2012 fnh, hendrich@informatik.uni-hamburg.de
-->
    <!-- <material name="black">
    <color rgba="0.0 0.0 0.0 1.0"/>
  </material> -->
    <!-- <material name="blue">
    <color rgba="0.0 0.0 0.8 1.0"/>
  </material>
  
  <material name="green">
    <color rgba="0.0 0.8 0.0 1.0"/>
  </material> -->
    <material name="gray">
        <color rgba="0.2 0.2 0.2 1.0" />
    </material>
    <!-- <material name="lightgray">
    <color rgba="0.6 0.6 0.6 1.0"/>
  </material>
  
  <material name="darkgray">
    <color rgba="0.4 0.4 0.4 1.0"/>
  </material> -->
    <material name="marimba_key">
        <color rgba="0.5 0.3 0.1 1.0" />
    </material>
    <!-- <material name="orange">
    <color rgba="0.95 0.64 0.0 1.0"/>
  </material>

  <material name="yellow">
    <color rgba="0.9 0.9 0.0 1.0"/>
  </material>

  <material name="gold">
    <color rgba="0.7 0.7 0.0 1.0"/>
  </material>

  <material name="silver">
    <color rgba="0.95 0.95 0.95 1.0"/>
  </material>
  
  <material name="white">
    <color rgba="1.0 1.0 1.0 1.0"/>
  </material> -->
    <!-- URDF/Gazebo model of a marimba.

Coordinate system:

From the point of view of the marimbist:
    x: points towards you
    y: points towards the right
    z: points towards the ceiling, according to right hand rule


Changelog:
    2023.03.02 Named and correctly positioned bar frames
               Added side boxes
    2023.01.26 Complete model v1
    2023.01.19 Row of keys working
    2023.01.04 First version created
-->
    <link name="marimba">
        <default_inertial_with_mass inertial="1" mass="0.001" />
    </link>
    <gazebo reference="marimba">
        <turnGravityOff>false</turnGravityOff>
        <selfCollide>true</selfCollide>
        <!-- TODO material -->
        <!--<material>Gazebo/Green</material>-->
        <mu1>50.0</mu1>
        <mu2>50.0</mu2>
        <kp>1000000.0</kp>
        <kd>1.0</kd>
    </gazebo>
    <!-- Bottom body -->
    <gazebo reference="body_bottom">
        <turnGravityOff>false</turnGravityOff>
        <selfCollide>true</selfCollide>
        <!-- TODO material -->
        <!-- <material>chordophones/OakWood</material> -->
        <mu1>50.0</mu1>
        <mu2>50.0</mu2>
        <kp>1000000.0</kp>
        <kd>1.0</kd>
    </gazebo>
    <link name="body_bottom">
        <inertial>
            <mass value="7.5" />
            <origin rpy="0 0 0" xyz="0 0 0" />
            <inertia ixx="0.2" ixy="0" ixz="0" iyy="0.2" iyz="0" izz="0.05" />
        </inertial>
        <visual>
            <origin rpy="0 0 0.18" xyz="0 0 0" />
            <geometry>
                <!-- <mesh filename="package://chordophones/meshes/guzheng-body.stl"  scale="0.001 0.001 0.001" /> -->
                <box size="0.2 0.82 0.03" />
            </geometry>
            <material name="gray" />
        </visual>
        <collision>
            <origin rpy="0 0 0.18" xyz="0 0 0" />
            <geometry>
                <box size="0.2 0.82 0.03" />
            </geometry>
        </collision>
    </link>
    <joint name="body_bottom/fixedjoint" type="fixed">
        <origin rpy="0 0 0" xyz="0 0 0" />
        <parent link="marimba" />
        <child link="body_bottom" />
    </joint>
    <!-- Top body -->
    <gazebo reference="body_top">
        <turnGravityOff>false</turnGravityOff>
        <selfCollide>true</selfCollide>
        <!-- TODO material -->
        <!-- <material>chordophones/OakWood</material> -->
        <mu1>50.0</mu1>
        <mu2>50.0</mu2>
        <kp>1000000.0</kp>
        <kd>1.0</kd>
    </gazebo>
    <link name="body_top">
        <inertial>
            <mass value="7.5" />
            <origin rpy="0 0 0" xyz="0 0 0" />
            <inertia ixx="0.2" ixy="0" ixz="0" iyy="0.2" iyz="0" izz="0.05" />
        </inertial>
        <visual>
            <origin rpy="0 0 -0.15" xyz="     -0.18     -0.02     0.0334" />
            <geometry>
                <!-- <mesh filename="package://chordophones/meshes/guzheng-body.stl"  scale="0.001 0.001 0.001" /> -->
                <box size="0.12 0.75 0.03" />
            </geometry>
            <material name="gray" />
        </visual>
        <collision>
            <origin rpy="0 0 -0.15" xyz="     -0.18     -0.02     0.0334" />
            <geometry>
                <box size="0.12 0.75 0.03" />
            </geometry>
        </collision>
    </link>
    <joint name="body_top/fixedjoint" type="fixed">
        <origin rpy="0 0 0" xyz="0 0 0" />
        <parent link="marimba" />
        <child link="body_top" />
    </joint>
    <!-- Left side box -->
    <gazebo reference="body_left">
        <turnGravityOff>false</turnGravityOff>
        <selfCollide>true</selfCollide>
        <!-- TODO material -->
        <!-- <material>chordophones/OakWood</material> -->
        <mu1>50.0</mu1>
        <mu2>50.0</mu2>
        <kp>1000000.0</kp>
        <kd>1.0</kd>
    </gazebo>
    <link name="body_left">
        <inertial>
            <mass value="7.5" />
            <origin rpy="0 0 0" xyz="0 0 0" />
            <inertia ixx="0.2" ixy="0" ixz="0" iyy="0.2" iyz="0" izz="0.05" />
        </inertial>
        <visual>
            <origin rpy="0 0 1.57" xyz="     -0.07999999999999999     -0.453     0.0335" />
            <geometry>
                <!-- <mesh filename="package://chordophones/meshes/guzheng-body.stl"  scale="0.001 0.001 0.001" /> -->
                <box size="0.05 0.61 0.1" />
            </geometry>
            <material name="gray" />
        </visual>
        <collision>
            <origin rpy="0 0 1.57" xyz="     -0.07999999999999999     -0.453     0.0335" />
            <geometry>
                <box size="0.05 0.61 0.1" />
            </geometry>
        </collision>
    </link>
    <joint name="body_left/fixedjoint" type="fixed">
        <origin rpy="0 0 0" xyz="0 0 0" />
        <parent link="marimba" />
        <child link="body_left" />
    </joint>
    <!-- Right side box -->
    <gazebo reference="body_right">
        <turnGravityOff>false</turnGravityOff>
        <selfCollide>true</selfCollide>
        <!-- TODO material -->
        <!-- <material>chordophones/OakWood</material> -->
        <mu1>50.0</mu1>
        <mu2>50.0</mu2>
        <kp>1000000.0</kp>
        <kd>1.0</kd>
    </gazebo>
    <link name="body_right">
        <inertial>
            <mass value="7.5" />
            <origin rpy="0 0 0" xyz="0 0 0" />
            <inertia ixx="0.2" ixy="0" ixz="0" iyy="0.2" iyz="0" izz="0.05" />
        </inertial>
        <visual>
            <origin rpy="0 0 1.57" xyz="     -0.07999999999999999     0.46935000000000004     0.0335" />
            <geometry>
                <!-- <mesh filename="package://chordophones/meshes/guzheng-body.stl"  scale="0.001 0.001 0.001" /> -->
                <box size="0.05 0.32 0.1" />
            </geometry>
            <material name="gray" />
        </visual>
        <collision>
            <origin rpy="0 0 1.57" xyz="     -0.07999999999999999     0.46935000000000004     0.0335" />
            <geometry>
                <box size="0.05 0.32 0.1" />
            </geometry>
        </collision>
    </link>
    <joint name="body_right/fixedjoint" type="fixed">
        <origin rpy="0 0 0" xyz="0 0 0" />
        <parent link="marimba" />
        <child link="body_right" />
    </joint>
    <gazebo reference="bar_C4">
        <turnGravityOff>false</turnGravityOff>
        <selfCollide>true</selfCollide>
        <!-- TODO material -->
        <!-- <material>chordophones/OakWood</material> -->
        <mu1>50.0</mu1>
        <mu2>50.0</mu2>
        <kp>1000000.0</kp>
        <kd>1.0</kd>
    </gazebo>
    <link name="bar_C4">
        <inertial>
            <mass value="0.03" />
            <origin rpy="0 0 0" xyz="0 0 0" />
            <inertia ixx="0.01" ixy="0" ixz="0" iyy="0.01" iyz="0" izz="0.01" />
        </inertial>
        <visual>
            <origin rpy="0 0 0" xyz="0 0 -0.00925" />
            <geometry>
                <box size="0.32 0.0323 0.0185" />
            </geometry>
            <!-- TODO material -->
            <!-- <material name="oak_wood" /> -->
            <material name="marimba_key" />
        </visual>
        <collision>
            <origin rpy="0 0 0" xyz="0 0 -0.00925" />
            <geometry>
                <box size="0.32 0.0323 0.0185" />
            </geometry>
        </collision>
    </link>
    <joint name="bar_C4/joint" type="fixed">
        <origin rpy="0 0 0" xyz="0.05 -0.41 0.0335" />
        <parent link="body_bottom" />
        <child link="bar_C4" />
    </joint>
    <transmission name="bar_C4/joint_transmission">
        <type>transmission_interface/SimpleTransmission</type>
        <joint name="bar_C4/joint">
            <hardwareInterface>hardware_interface/EffortJointInterface</hardwareInterface>
        </joint>
        <actuator name="bar_C4/joint_motor">
            <mechanicalReduction>1</mechanicalReduction>
        </actuator>
    </transmission>
    <gazebo reference="bar_D4">
        <turnGravityOff>false</turnGravityOff>
        <selfCollide>true</selfCollide>
        <!-- TODO material -->
        <!-- <material>chordophones/OakWood</material> -->
        <mu1>50.0</mu1>
        <mu2>50.0</mu2>
        <kp>1000000.0</kp>
        <kd>1.0</kd>
    </gazebo>
    <link name="bar_D4">
        <inertial>
            <mass value="0.03" />
            <origin rpy="0 0 0" xyz="0 0 0" />
            <inertia ixx="0.01" ixy="0" ixz="0" iyy="0.01" iyz="0" izz="0.01" />
        </inertial>
        <visual>
            <origin rpy="0 0 0" xyz="0 0 -0.00925" />
            <geometry>
                <box size="0.31331818181818183 0.0323 0.0185" />
            </geometry>
            <!-- TODO material -->
            <!-- <material name="oak_wood" /> -->
            <material name="marimba_key" />
        </visual>
        <collision>
            <origin rpy="0 0 0" xyz="0 0 -0.00925" />
            <geometry>
                <box size="0.31331818181818183 0.0323 0.0185" />
            </geometry>
        </collision>
    </link>
    <joint name="bar_D4/joint" type="fixed">
        <origin rpy="0 0 0" xyz="0.047828409090909095 -0.3702 0.0335" />
        <parent link="body_bottom" />
        <child link="bar_D4" />
    </joint>
    <transmission name="bar_D4/joint_transmission">
        <type>transmission_interface/SimpleTransmission</type>
        <joint name="bar_D4/joint">
            <hardwareInterface>hardware_interface/EffortJointInterface</hardwareInterface>
        </joint>
        <actuator name="bar_D4/joint_motor">
            <mechanicalReduction>1</mechanicalReduction>
        </actuator>
    </transmission>
    <gazebo reference="bar_E4">
        <turnGravityOff>false</turnGravityOff>
        <selfCollide>true</selfCollide>
        <!-- TODO material -->
        <!-- <material>chordophones/OakWood</material> -->
        <mu1>50.0</mu1>
        <mu2>50.0</mu2>
        <kp>1000000.0</kp>
        <kd>1.0</kd>
    </gazebo>
    <link name="bar_E4">
        <inertial>
            <mass value="0.03" />
            <origin rpy="0 0 0" xyz="0 0 0" />
            <inertia ixx="0.01" ixy="0" ixz="0" iyy="0.01" iyz="0" izz="0.01" />
        </inertial>
        <visual>
            <origin rpy="0 0 0" xyz="0 0 -0.00925" />
            <geometry>
                <box size="0.30663636363636365 0.0323 0.0185" />
            </geometry>
            <!-- TODO material -->
            <!-- <material name="oak_wood" /> -->
            <material name="marimba_key" />
        </visual>
        <collision>
            <origin rpy="0 0 0" xyz="0 0 -0.00925" />
            <geometry>
                <box size="0.30663636363636365 0.0323 0.0185" />
            </geometry>
        </collision>
    </link>
    <joint name="bar_E4/joint" type="fixed">
        <origin rpy="0 0 0" xyz="0.04565681818181819 -0.33039999999999997 0.0335" />
        <parent link="body_bottom" />
        <child link="bar_E4" />
    </joint>
    <transmission name="bar_E4/joint_transmission">
        <type>transmission_interface/SimpleTransmission</type>
        <joint name="bar_E4/joint">
            <hardwareInterface>hardware_interface/EffortJointInterface</hardwareInterface>
        </joint>
        <actuator name="bar_E4/joint_motor">
            <mechanicalReduction>1</mechanicalReduction>
        </actuator>
    </transmission>
    <gazebo reference="bar_F4">
        <turnGravityOff>false</turnGravityOff>
        <selfCollide>true</selfCollide>
        <!-- TODO material -->
        <!-- <material>chordophones/OakWood</material> -->
        <mu1>50.0</mu1>
        <mu2>50.0</mu2>
        <kp>1000000.0</kp>
        <kd>1.0</kd>
    </gazebo>
    <link name="bar_F4">
        <inertial>
            <mass value="0.03" />
            <origin rpy="0 0 0" xyz="0 0 0" />
            <inertia ixx="0.01" ixy="0" ixz="0" iyy="0.01" iyz="0" izz="0.01" />
        </inertial>
        <visual>
            <origin rpy="0 0 0" xyz="0 0 -0.00925" />
            <geometry>
                <box size="0.2999545454545455 0.0323 0.0185" />
            </geometry>
            <!-- TODO material -->
            <!-- <material name="oak_wood" /> -->
            <material name="marimba_key" />
        </visual>
        <collision>
            <origin rpy="0 0 0" xyz="0 0 -0.00925" />
            <geometry>
                <box size="0.2999545454545455 0.0323 0.0185" />
            </geometry>
        </collision>
    </link>
    <joint name="bar_F4/joint" type="fixed">
        <origin rpy="0 0 0" xyz="0.04348522727272727 -0.29059999999999997 0.0335" />
        <parent link="body_bottom" />
        <child link="bar_F4" />
    </joint>
    <transmission name="bar_F4/joint_transmission">
        <type>transmission_interface/SimpleTransmission</type>
        <joint name="bar_F4/joint">
            <hardwareInterface>hardware_interface/EffortJointInterface</hardwareInterface>
        </joint>
        <actuator name="bar_F4/joint_motor">
            <mechanicalReduction>1</mechanicalReduction>
        </actuator>
    </transmission>
    <gazebo reference="bar_G4">
        <turnGravityOff>false</turnGravityOff>
        <selfCollide>true</selfCollide>
        <!-- TODO material -->
        <!-- <material>chordophones/OakWood</material> -->
        <mu1>50.0</mu1>
        <mu2>50.0</mu2>
        <kp>1000000.0</kp>
        <kd>1.0</kd>
    </gazebo>
    <link name="bar_G4">
        <inertial>
            <mass value="0.03" />
            <origin rpy="0 0 0" xyz="0 0 0" />
            <inertia ixx="0.01" ixy="0" ixz="0" iyy="0.01" iyz="0" izz="0.01" />
        </inertial>
        <visual>
            <origin rpy="0 0 0" xyz="0 0 -0.00925" />
            <geometry>
                <box size="0.2932727272727273 0.0323 0.0185" />
            </geometry>
            <!-- TODO material -->
            <!-- <material name="oak_wood" /> -->
            <material name="marimba_key" />
        </visual>
        <collision>
            <origin rpy="0 0 0" xyz="0 0 -0.00925" />
            <geometry>
                <box size="0.2932727272727273 0.0323 0.0185" />
            </geometry>
        </collision>
    </link>
    <joint name="bar_G4/joint" type="fixed">
        <origin rpy="0 0 0" xyz="0.041313636363636365 -0.25079999999999997 0.0335" />
        <parent link="body_bottom" />
        <child link="bar_G4" />
    </joint>
    <transmission name="bar_G4/joint_transmission">
        <type>transmission_interface/SimpleTransmission</type>
        <joint name="bar_G4/joint">
            <hardwareInterface>hardware_interface/EffortJointInterface</hardwareInterface>
        </joint>
        <actuator name="bar_G4/joint_motor">
            <mechanicalReduction>1</mechanicalReduction>
        </actuator>
    </transmission>
    <gazebo reference="bar_A4">
        <turnGravityOff>false</turnGravityOff>
        <selfCollide>true</selfCollide>
        <!-- TODO material -->
        <!-- <material>chordophones/OakWood</material> -->
        <mu1>50.0</mu1>
        <mu2>50.0</mu2>
        <kp>1000000.0</kp>
        <kd>1.0</kd>
    </gazebo>
    <link name="bar_A4">
        <inertial>
            <mass value="0.03" />
            <origin rpy="0 0 0" xyz="0 0 0" />
            <inertia ixx="0.01" ixy="0" ixz="0" iyy="0.01" iyz="0" izz="0.01" />
        </inertial>
        <visual>
            <origin rpy="0 0 0" xyz="0 0 -0.00925" />
            <geometry>
                <box size="0.2865909090909091 0.0323 0.0185" />
            </geometry>
            <!-- TODO material -->
            <!-- <material name="oak_wood" /> -->
            <material name="marimba_key" />
        </visual>
        <collision>
            <origin rpy="0 0 0" xyz="0 0 -0.00925" />
            <geometry>
                <box size="0.2865909090909091 0.0323 0.0185" />
            </geometry>
        </collision>
    </link>
    <joint name="bar_A4/joint" type="fixed">
        <origin rpy="0 0 0" xyz="0.03914204545454546 -0.21099999999999997 0.0335" />
        <parent link="body_bottom" />
        <child link="bar_A4" />
    </joint>
    <transmission name="bar_A4/joint_transmission">
        <type>transmission_interface/SimpleTransmission</type>
        <joint name="bar_A4/joint">
            <hardwareInterface>hardware_interface/EffortJointInterface</hardwareInterface>
        </joint>
        <actuator name="bar_A4/joint_motor">
            <mechanicalReduction>1</mechanicalReduction>
        </actuator>
    </transmission>
    <gazebo reference="bar_B4">
        <turnGravityOff>false</turnGravityOff>
        <selfCollide>true</selfCollide>
        <!-- TODO material -->
        <!-- <material>chordophones/OakWood</material> -->
        <mu1>50.0</mu1>
        <mu2>50.0</mu2>
        <kp>1000000.0</kp>
        <kd>1.0</kd>
    </gazebo>
    <link name="bar_B4">
        <inertial>
            <mass value="0.03" />
            <origin rpy="0 0 0" xyz="0 0 0" />
            <inertia ixx="0.01" ixy="0" ixz="0" iyy="0.01" iyz="0" izz="0.01" />
        </inertial>
        <visual>
            <origin rpy="0 0 0" xyz="0 0 -0.00925" />
            <geometry>
                <box size="0.2799090909090909 0.0323 0.0185" />
            </geometry>
            <!-- TODO material -->
            <!-- <material name="oak_wood" /> -->
            <material name="marimba_key" />
        </visual>
        <collision>
            <origin rpy="0 0 0" xyz="0 0 -0.00925" />
            <geometry>
                <box size="0.2799090909090909 0.0323 0.0185" />
            </geometry>
        </collision>
    </link>
    <joint name="bar_B4/joint" type="fixed">
        <origin rpy="0 0 0" xyz="0.03697045454545454 -0.17119999999999996 0.0335" />
        <parent link="body_bottom" />
        <child link="bar_B4" />
    </joint>
    <transmission name="bar_B4/joint_transmission">
        <type>transmission_interface/SimpleTransmission</type>
        <joint name="bar_B4/joint">
            <hardwareInterface>hardware_interface/EffortJointInterface</hardwareInterface>
        </joint>
        <actuator name="bar_B4/joint_motor">
            <mechanicalReduction>1</mechanicalReduction>
        </actuator>
    </transmission>
    <gazebo reference="bar_C5">
        <turnGravityOff>false</turnGravityOff>
        <selfCollide>true</selfCollide>
        <!-- TODO material -->
        <!-- <material>chordophones/OakWood</material> -->
        <mu1>50.0</mu1>
        <mu2>50.0</mu2>
        <kp>1000000.0</kp>
        <kd>1.0</kd>
    </gazebo>
    <link name="bar_C5">
        <inertial>
            <mass value="0.03" />
            <origin rpy="0 0 0" xyz="0 0 0" />
            <inertia ixx="0.01" ixy="0" ixz="0" iyy="0.01" iyz="0" izz="0.01" />
        </inertial>
        <visual>
            <origin rpy="0 0 0" xyz="0 0 -0.00925" />
            <geometry>
                <box size="0.2732272727272727 0.0323 0.0185" />
            </geometry>
            <!-- TODO material -->
            <!-- <material name="oak_wood" /> -->
            <material name="marimba_key" />
        </visual>
        <collision>
            <origin rpy="0 0 0" xyz="0 0 -0.00925" />
            <geometry>
                <box size="0.2732272727272727 0.0323 0.0185" />
            </geometry>
        </collision>
    </link>
    <joint name="bar_C5/joint" type="fixed">
        <origin rpy="0 0 0" xyz="0.034798863636363635 -0.13139999999999996 0.0335" />
        <parent link="body_bottom" />
        <child link="bar_C5" />
    </joint>
    <transmission name="bar_C5/joint_transmission">
        <type>transmission_interface/SimpleTransmission</type>
        <joint name="bar_C5/joint">
            <hardwareInterface>hardware_interface/EffortJointInterface</hardwareInterface>
        </joint>
        <actuator name="bar_C5/joint_motor">
            <mechanicalReduction>1</mechanicalReduction>
        </actuator>
    </transmission>
    <gazebo reference="bar_D5">
        <turnGravityOff>false</turnGravityOff>
        <selfCollide>true</selfCollide>
        <!-- TODO material -->
        <!-- <material>chordophones/OakWood</material> -->
        <mu1>50.0</mu1>
        <mu2>50.0</mu2>
        <kp>1000000.0</kp>
        <kd>1.0</kd>
    </gazebo>
    <link name="bar_D5">
        <inertial>
            <mass value="0.03" />
            <origin rpy="0 0 0" xyz="0 0 0" />
            <inertia ixx="0.01" ixy="0" ixz="0" iyy="0.01" iyz="0" izz="0.01" />
        </inertial>
        <visual>
            <origin rpy="0 0 0" xyz="0 0 -0.00925" />
            <geometry>
                <box size="0.26654545454545453 0.0323 0.0185" />
            </geometry>
            <!-- TODO material -->
            <!-- <material name="oak_wood" /> -->
            <material name="marimba_key" />
        </visual>
        <collision>
            <origin rpy="0 0 0" xyz="0 0 -0.00925" />
            <geometry>
                <box size="0.26654545454545453 0.0323 0.0185" />
            </geometry>
        </collision>
    </link>
    <joint name="bar_D5/joint" type="fixed">
        <origin rpy="0 0 0" xyz="0.03262727272727273 -0.09159999999999996 0.0335" />
        <parent link="body_bottom" />
        <child link="bar_D5" />
    </joint>
    <transmission name="bar_D5/joint_transmission">
        <type>transmission_interface/SimpleTransmission</type>
        <joint name="bar_D5/joint">
            <hardwareInterface>hardware_interface/EffortJointInterface</hardwareInterface>
        </joint>
        <actuator name="bar_D5/joint_motor">
            <mechanicalReduction>1</mechanicalReduction>
        </actuator>
    </transmission>
    <gazebo reference="bar_E5">
        <turnGravityOff>false</turnGravityOff>
        <selfCollide>true</selfCollide>
        <!-- TODO material -->
        <!-- <material>chordophones/OakWood</material> -->
        <mu1>50.0</mu1>
        <mu2>50.0</mu2>
        <kp>1000000.0</kp>
        <kd>1.0</kd>
    </gazebo>
    <link name="bar_E5">
        <inertial>
            <mass value="0.03" />
            <origin rpy="0 0 0" xyz="0 0 0" />
            <inertia ixx="0.01" ixy="0" ixz="0" iyy="0.01" iyz="0" izz="0.01" />
        </inertial>
        <visual>
            <origin rpy="0 0 0" xyz="0 0 -0.00925" />
            <geometry>
                <box size="0.25986363636363635 0.0323 0.0185" />
            </geometry>
            <!-- TODO material -->
            <!-- <material name="oak_wood" /> -->
            <material name="marimba_key" />
        </visual>
        <collision>
            <origin rpy="0 0 0" xyz="0 0 -0.00925" />
            <geometry>
                <box size="0.25986363636363635 0.0323 0.0185" />
            </geometry>
        </collision>
    </link>
    <joint name="bar_E5/joint" type="fixed">
        <origin rpy="0 0 0" xyz="0.030455681818181816 -0.05179999999999996 0.0335" />
        <parent link="body_bottom" />
        <child link="bar_E5" />
    </joint>
    <transmission name="bar_E5/joint_transmission">
        <type>transmission_interface/SimpleTransmission</type>
        <joint name="bar_E5/joint">
            <hardwareInterface>hardware_interface/EffortJointInterface</hardwareInterface>
        </joint>
        <actuator name="bar_E5/joint_motor">
            <mechanicalReduction>1</mechanicalReduction>
        </actuator>
    </transmission>
    <gazebo reference="bar_F5">
        <turnGravityOff>false</turnGravityOff>
        <selfCollide>true</selfCollide>
        <!-- TODO material -->
        <!-- <material>chordophones/OakWood</material> -->
        <mu1>50.0</mu1>
        <mu2>50.0</mu2>
        <kp>1000000.0</kp>
        <kd>1.0</kd>
    </gazebo>
    <link name="bar_F5">
        <inertial>
            <mass value="0.03" />
            <origin rpy="0 0 0" xyz="0 0 0" />
            <inertia ixx="0.01" ixy="0" ixz="0" iyy="0.01" iyz="0" izz="0.01" />
        </inertial>
        <visual>
            <origin rpy="0 0 0" xyz="0 0 -0.00925" />
            <geometry>
                <box size="0.2531818181818182 0.0323 0.0185" />
            </geometry>
            <!-- TODO material -->
            <!-- <material name="oak_wood" /> -->
            <material name="marimba_key" />
        </visual>
        <collision>
            <origin rpy="0 0 0" xyz="0 0 -0.00925" />
            <geometry>
                <box size="0.2531818181818182 0.0323 0.0185" />
            </geometry>
        </collision>
    </link>
    <joint name="bar_F5/joint" type="fixed">
        <origin rpy="0 0 0" xyz="0.028284090909090908 -0.011999999999999955 0.0335" />
        <parent link="body_bottom" />
        <child link="bar_F5" />
    </joint>
    <transmission name="bar_F5/joint_transmission">
        <type>transmission_interface/SimpleTransmission</type>
        <joint name="bar_F5/joint">
            <hardwareInterface>hardware_interface/EffortJointInterface</hardwareInterface>
        </joint>
        <actuator name="bar_F5/joint_motor">
            <mechanicalReduction>1</mechanicalReduction>
        </actuator>
    </transmission>
    <gazebo reference="bar_G5">
        <turnGravityOff>false</turnGravityOff>
        <selfCollide>true</selfCollide>
        <!-- TODO material -->
        <!-- <material>chordophones/OakWood</material> -->
        <mu1>50.0</mu1>
        <mu2>50.0</mu2>
        <kp>1000000.0</kp>
        <kd>1.0</kd>
    </gazebo>
    <link name="bar_G5">
        <inertial>
            <mass value="0.03" />
            <origin rpy="0 0 0" xyz="0 0 0" />
            <inertia ixx="0.01" ixy="0" ixz="0" iyy="0.01" iyz="0" izz="0.01" />
        </inertial>
        <visual>
            <origin rpy="0 0 0" xyz="0 0 -0.00925" />
            <geometry>
                <box size="0.2465 0.0323 0.0185" />
            </geometry>
            <!-- TODO material -->
            <!-- <material name="oak_wood" /> -->
            <material name="marimba_key" />
        </visual>
        <collision>
            <origin rpy="0 0 0" xyz="0 0 -0.00925" />
            <geometry>
                <box size="0.2465 0.0323 0.0185" />
            </geometry>
        </collision>
    </link>
    <joint name="bar_G5/joint" type="fixed">
        <origin rpy="0 0 0" xyz="0.0261125 0.027800000000000047 0.0335" />
        <parent link="body_bottom" />
        <child link="bar_G5" />
    </joint>
    <transmission name="bar_G5/joint_transmission">
        <type>transmission_interface/SimpleTransmission</type>
        <joint name="bar_G5/joint">
            <hardwareInterface>hardware_interface/EffortJointInterface</hardwareInterface>
        </joint>
        <actuator name="bar_G5/joint_motor">
            <mechanicalReduction>1</mechanicalReduction>
        </actuator>
    </transmission>
    <gazebo reference="bar_A5">
        <turnGravityOff>false</turnGravityOff>
        <selfCollide>true</selfCollide>
        <!-- TODO material -->
        <!-- <material>chordophones/OakWood</material> -->
        <mu1>50.0</mu1>
        <mu2>50.0</mu2>
        <kp>1000000.0</kp>
        <kd>1.0</kd>
    </gazebo>
    <link name="bar_A5">
        <inertial>
            <mass value="0.03" />
            <origin rpy="0 0 0" xyz="0 0 0" />
            <inertia ixx="0.01" ixy="0" ixz="0" iyy="0.01" iyz="0" izz="0.01" />
        </inertial>
        <visual>
            <origin rpy="0 0 0" xyz="0 0 -0.00925" />
            <geometry>
                <box size="0.23981818181818182 0.0323 0.0185" />
            </geometry>
            <!-- TODO material -->
            <!-- <material name="oak_wood" /> -->
            <material name="marimba_key" />
        </visual>
        <collision>
            <origin rpy="0 0 0" xyz="0 0 -0.00925" />
            <geometry>
                <box size="0.23981818181818182 0.0323 0.0185" />
            </geometry>
        </collision>
    </link>
    <joint name="bar_A5/joint" type="fixed">
        <origin rpy="0 0 0" xyz="0.02394090909090909 0.06760000000000005 0.0335" />
        <parent link="body_bottom" />
        <child link="bar_A5" />
    </joint>
    <transmission name="bar_A5/joint_transmission">
        <type>transmission_interface/SimpleTransmission</type>
        <joint name="bar_A5/joint">
            <hardwareInterface>hardware_interface/EffortJointInterface</hardwareInterface>
        </joint>
        <actuator name="bar_A5/joint_motor">
            <mechanicalReduction>1</mechanicalReduction>
        </actuator>
    </transmission>
    <gazebo reference="bar_B5">
        <turnGravityOff>false</turnGravityOff>
        <selfCollide>true</selfCollide>
        <!-- TODO material -->
        <!-- <material>chordophones/OakWood</material> -->
        <mu1>50.0</mu1>
        <mu2>50.0</mu2>
        <kp>1000000.0</kp>
        <kd>1.0</kd>
    </gazebo>
    <link name="bar_B5">
        <inertial>
            <mass value="0.03" />
            <origin rpy="0 0 0" xyz="0 0 0" />
            <inertia ixx="0.01" ixy="0" ixz="0" iyy="0.01" iyz="0" izz="0.01" />
        </inertial>
        <visual>
            <origin rpy="0 0 0" xyz="0 0 -0.00925" />
            <geometry>
                <box size="0.23313636363636364 0.0323 0.0185" />
            </geometry>
            <!-- TODO material -->
            <!-- <material name="oak_wood" /> -->
            <material name="marimba_key" />
        </visual>
        <collision>
            <origin rpy="0 0 0" xyz="0 0 -0.00925" />
            <geometry>
                <box size="0.23313636363636364 0.0323 0.0185" />
            </geometry>
        </collision>
    </link>
    <joint name="bar_B5/joint" type="fixed">
        <origin rpy="0 0 0" xyz="0.021769318181818178 0.1074000000000001 0.0335" />
        <parent link="body_bottom" />
        <child link="bar_B5" />
    </joint>
    <transmission name="bar_B5/joint_transmission">
        <type>transmission_interface/SimpleTransmission</type>
        <joint name="bar_B5/joint">
            <hardwareInterface>hardware_interface/EffortJointInterface</hardwareInterface>
        </joint>
        <actuator name="bar_B5/joint_motor">
            <mechanicalReduction>1</mechanicalReduction>
        </actuator>
    </transmission>
    <gazebo reference="bar_C6">
        <turnGravityOff>false</turnGravityOff>
        <selfCollide>true</selfCollide>
        <!-- TODO material -->
        <!-- <material>chordophones/OakWood</material> -->
        <mu1>50.0</mu1>
        <mu2>50.0</mu2>
        <kp>1000000.0</kp>
        <kd>1.0</kd>
    </gazebo>
    <link name="bar_C6">
        <inertial>
            <mass value="0.03" />
            <origin rpy="0 0 0" xyz="0 0 0" />
            <inertia ixx="0.01" ixy="0" ixz="0" iyy="0.01" iyz="0" izz="0.01" />
        </inertial>
        <visual>
            <origin rpy="0 0 0" xyz="0 0 -0.00925" />
            <geometry>
                <box size="0.22645454545454546 0.0323 0.0185" />
            </geometry>
            <!-- TODO material -->
            <!-- <material name="oak_wood" /> -->
            <material name="marimba_key" />
        </visual>
        <collision>
            <origin rpy="0 0 0" xyz="0 0 -0.00925" />
            <geometry>
                <box size="0.22645454545454546 0.0323 0.0185" />
            </geometry>
        </collision>
    </link>
    <joint name="bar_C6/joint" type="fixed">
        <origin rpy="0 0 0" xyz="0.01959772727272727 0.14720000000000005 0.0335" />
        <parent link="body_bottom" />
        <child link="bar_C6" />
    </joint>
    <transmission name="bar_C6/joint_transmission">
        <type>transmission_interface/SimpleTransmission</type>
        <joint name="bar_C6/joint">
            <hardwareInterface>hardware_interface/EffortJointInterface</hardwareInterface>
        </joint>
        <actuator name="bar_C6/joint_motor">
            <mechanicalReduction>1</mechanicalReduction>
        </actuator>
    </transmission>
    <gazebo reference="bar_D6">
        <turnGravityOff>false</turnGravityOff>
        <selfCollide>true</selfCollide>
        <!-- TODO material -->
        <!-- <material>chordophones/OakWood</material> -->
        <mu1>50.0</mu1>
        <mu2>50.0</mu2>
        <kp>1000000.0</kp>
        <kd>1.0</kd>
    </gazebo>
    <link name="bar_D6">
        <inertial>
            <mass value="0.03" />
            <origin rpy="0 0 0" xyz="0 0 0" />
            <inertia ixx="0.01" ixy="0" ixz="0" iyy="0.01" iyz="0" izz="0.01" />
        </inertial>
        <visual>
            <origin rpy="0 0 0" xyz="0 0 -0.00925" />
            <geometry>
                <box size="0.2197727272727273 0.0323 0.0185" />
            </geometry>
            <!-- TODO material -->
            <!-- <material name="oak_wood" /> -->
            <material name="marimba_key" />
        </visual>
        <collision>
            <origin rpy="0 0 0" xyz="0 0 -0.00925" />
            <geometry>
                <box size="0.2197727272727273 0.0323 0.0185" />
            </geometry>
        </collision>
    </link>
    <joint name="bar_D6/joint" type="fixed">
        <origin rpy="0 0 0" xyz="0.017426136363636366 0.187 0.0335" />
        <parent link="body_bottom" />
        <child link="bar_D6" />
    </joint>
    <transmission name="bar_D6/joint_transmission">
        <type>transmission_interface/SimpleTransmission</type>
        <joint name="bar_D6/joint">
            <hardwareInterface>hardware_interface/EffortJointInterface</hardwareInterface>
        </joint>
        <actuator name="bar_D6/joint_motor">
            <mechanicalReduction>1</mechanicalReduction>
        </actuator>
    </transmission>
    <gazebo reference="bar_E6">
        <turnGravityOff>false</turnGravityOff>
        <selfCollide>true</selfCollide>
        <!-- TODO material -->
        <!-- <material>chordophones/OakWood</material> -->
        <mu1>50.0</mu1>
        <mu2>50.0</mu2>
        <kp>1000000.0</kp>
        <kd>1.0</kd>
    </gazebo>
    <link name="bar_E6">
        <inertial>
            <mass value="0.03" />
            <origin rpy="0 0 0" xyz="0 0 0" />
            <inertia ixx="0.01" ixy="0" ixz="0" iyy="0.01" iyz="0" izz="0.01" />
        </inertial>
        <visual>
            <origin rpy="0 0 0" xyz="0 0 -0.00925" />
            <geometry>
                <box size="0.21309090909090908 0.0323 0.0185" />
            </geometry>
            <!-- TODO material -->
            <!-- <material name="oak_wood" /> -->
            <material name="marimba_key" />
        </visual>
        <collision>
            <origin rpy="0 0 0" xyz="0 0 -0.00925" />
            <geometry>
                <box size="0.21309090909090908 0.0323 0.0185" />
            </geometry>
        </collision>
    </link>
    <joint name="bar_E6/joint" type="fixed">
        <origin rpy="0 0 0" xyz="0.015254545454545451 0.22680000000000006 0.0335" />
        <parent link="body_bottom" />
        <child link="bar_E6" />
    </joint>
    <transmission name="bar_E6/joint_transmission">
        <type>transmission_interface/SimpleTransmission</type>
        <joint name="bar_E6/joint">
            <hardwareInterface>hardware_interface/EffortJointInterface</hardwareInterface>
        </joint>
        <actuator name="bar_E6/joint_motor">
            <mechanicalReduction>1</mechanicalReduction>
        </actuator>
    </transmission>
    <gazebo reference="bar_F6">
        <turnGravityOff>false</turnGravityOff>
        <selfCollide>true</selfCollide>
        <!-- TODO material -->
        <!-- <material>chordophones/OakWood</material> -->
        <mu1>50.0</mu1>
        <mu2>50.0</mu2>
        <kp>1000000.0</kp>
        <kd>1.0</kd>
    </gazebo>
    <link name="bar_F6">
        <inertial>
            <mass value="0.03" />
            <origin rpy="0 0 0" xyz="0 0 0" />
            <inertia ixx="0.01" ixy="0" ixz="0" iyy="0.01" iyz="0" izz="0.01" />
        </inertial>
        <visual>
            <origin rpy="0 0 0" xyz="0 0 -0.00925" />
            <geometry>
                <box size="0.2064090909090909 0.0323 0.0185" />
            </geometry>
            <!-- TODO material -->
            <!-- <material name="oak_wood" /> -->
            <material name="marimba_key" />
        </visual>
        <collision>
            <origin rpy="0 0 0" xyz="0 0 -0.00925" />
            <geometry>
                <box size="0.2064090909090909 0.0323 0.0185" />
            </geometry>
        </collision>
    </link>
    <joint name="bar_F6/joint" type="fixed">
        <origin rpy="0 0 0" xyz="0.013082954545454543 0.2666000000000001 0.0335" />
        <parent link="body_bottom" />
        <child link="bar_F6" />
    </joint>
    <transmission name="bar_F6/joint_transmission">
        <type>transmission_interface/SimpleTransmission</type>
        <joint name="bar_F6/joint">
            <hardwareInterface>hardware_interface/EffortJointInterface</hardwareInterface>
        </joint>
        <actuator name="bar_F6/joint_motor">
            <mechanicalReduction>1</mechanicalReduction>
        </actuator>
    </transmission>
    <gazebo reference="bar_G6">
        <turnGravityOff>false</turnGravityOff>
        <selfCollide>true</selfCollide>
        <!-- TODO material -->
        <!-- <material>chordophones/OakWood</material> -->
        <mu1>50.0</mu1>
        <mu2>50.0</mu2>
        <kp>1000000.0</kp>
        <kd>1.0</kd>
    </gazebo>
    <link name="bar_G6">
        <inertial>
            <mass value="0.03" />
            <origin rpy="0 0 0" xyz="0 0 0" />
            <inertia ixx="0.01" ixy="0" ixz="0" iyy="0.01" iyz="0" izz="0.01" />
        </inertial>
        <visual>
            <origin rpy="0 0 0" xyz="0 0 -0.00925" />
            <geometry>
                <box size="0.1997272727272727 0.0323 0.0185" />
            </geometry>
            <!-- TODO material -->
            <!-- <material name="oak_wood" /> -->
            <material name="marimba_key" />
        </visual>
        <collision>
            <origin rpy="0 0 0" xyz="0 0 -0.00925" />
            <geometry>
                <box size="0.1997272727272727 0.0323 0.0185" />
            </geometry>
        </collision>
    </link>
    <joint name="bar_G6/joint" type="fixed">
        <origin rpy="0 0 0" xyz="0.010911363636363629 0.30640000000000006 0.0335" />
        <parent link="body_bottom" />
        <child link="bar_G6" />
    </joint>
    <transmission name="bar_G6/joint_transmission">
        <type>transmission_interface/SimpleTransmission</type>
        <joint name="bar_G6/joint">
            <hardwareInterface>hardware_interface/EffortJointInterface</hardwareInterface>
        </joint>
        <actuator name="bar_G6/joint_motor">
            <mechanicalReduction>1</mechanicalReduction>
        </actuator>
    </transmission>
    <gazebo reference="bar_A6">
        <turnGravityOff>false</turnGravityOff>
        <selfCollide>true</selfCollide>
        <!-- TODO material -->
        <!-- <material>chordophones/OakWood</material> -->
        <mu1>50.0</mu1>
        <mu2>50.0</mu2>
        <kp>1000000.0</kp>
        <kd>1.0</kd>
    </gazebo>
    <link name="bar_A6">
        <inertial>
            <mass value="0.03" />
            <origin rpy="0 0 0" xyz="0 0 0" />
            <inertia ixx="0.01" ixy="0" ixz="0" iyy="0.01" iyz="0" izz="0.01" />
        </inertial>
        <visual>
            <origin rpy="0 0 0" xyz="0 0 -0.00925" />
            <geometry>
                <box size="0.19304545454545452 0.0323 0.0185" />
            </geometry>
            <!-- TODO material -->
            <!-- <material name="oak_wood" /> -->
            <material name="marimba_key" />
        </visual>
        <collision>
            <origin rpy="0 0 0" xyz="0 0 -0.00925" />
            <geometry>
                <box size="0.19304545454545452 0.0323 0.0185" />
            </geometry>
        </collision>
    </link>
    <joint name="bar_A6/joint" type="fixed">
        <origin rpy="0 0 0" xyz="0.008739772727272721 0.3462 0.0335" />
        <parent link="body_bottom" />
        <child link="bar_A6" />
    </joint>
    <transmission name="bar_A6/joint_transmission">
        <type>transmission_interface/SimpleTransmission</type>
        <joint name="bar_A6/joint">
            <hardwareInterface>hardware_interface/EffortJointInterface</hardwareInterface>
        </joint>
        <actuator name="bar_A6/joint_motor">
            <mechanicalReduction>1</mechanicalReduction>
        </actuator>
    </transmission>
    <gazebo reference="bar_B6">
        <turnGravityOff>false</turnGravityOff>
        <selfCollide>true</selfCollide>
        <!-- TODO material -->
        <!-- <material>chordophones/OakWood</material> -->
        <mu1>50.0</mu1>
        <mu2>50.0</mu2>
        <kp>1000000.0</kp>
        <kd>1.0</kd>
    </gazebo>
    <link name="bar_B6">
        <inertial>
            <mass value="0.03" />
            <origin rpy="0 0 0" xyz="0 0 0" />
            <inertia ixx="0.01" ixy="0" ixz="0" iyy="0.01" iyz="0" izz="0.01" />
        </inertial>
        <visual>
            <origin rpy="0 0 0" xyz="0 0 -0.00925" />
            <geometry>
                <box size="0.18636363636363637 0.0323 0.0185" />
            </geometry>
            <!-- TODO material -->
            <!-- <material name="oak_wood" /> -->
            <material name="marimba_key" />
        </visual>
        <collision>
            <origin rpy="0 0 0" xyz="0 0 -0.00925" />
            <geometry>
                <box size="0.18636363636363637 0.0323 0.0185" />
            </geometry>
        </collision>
    </link>
    <joint name="bar_B6/joint" type="fixed">
        <origin rpy="0 0 0" xyz="0.006568181818181813 0.38600000000000007 0.0335" />
        <parent link="body_bottom" />
        <child link="bar_B6" />
    </joint>
    <transmission name="bar_B6/joint_transmission">
        <type>transmission_interface/SimpleTransmission</type>
        <joint name="bar_B6/joint">
            <hardwareInterface>hardware_interface/EffortJointInterface</hardwareInterface>
        </joint>
        <actuator name="bar_B6/joint_motor">
            <mechanicalReduction>1</mechanicalReduction>
        </actuator>
    </transmission>
    <gazebo reference="bar_C7">
        <turnGravityOff>false</turnGravityOff>
        <selfCollide>true</selfCollide>
        <!-- TODO material -->
        <!-- <material>chordophones/OakWood</material> -->
        <mu1>50.0</mu1>
        <mu2>50.0</mu2>
        <kp>1000000.0</kp>
        <kd>1.0</kd>
    </gazebo>
    <link name="bar_C7">
        <inertial>
            <mass value="0.03" />
            <origin rpy="0 0 0" xyz="0 0 0" />
            <inertia ixx="0.01" ixy="0" ixz="0" iyy="0.01" iyz="0" izz="0.01" />
        </inertial>
        <visual>
            <origin rpy="0 0 0" xyz="0 0 -0.00925" />
            <geometry>
                <box size="0.17968181818181816 0.0323 0.0185" />
            </geometry>
            <!-- TODO material -->
            <!-- <material name="oak_wood" /> -->
            <material name="marimba_key" />
        </visual>
        <collision>
            <origin rpy="0 0 0" xyz="0 0 -0.00925" />
            <geometry>
                <box size="0.17968181818181816 0.0323 0.0185" />
            </geometry>
        </collision>
    </link>
    <joint name="bar_C7/joint" type="fixed">
        <origin rpy="0 0 0" xyz="0.0043965909090909056 0.4258000000000001 0.0335" />
        <parent link="body_bottom" />
        <child link="bar_C7" />
    </joint>
    <transmission name="bar_C7/joint_transmission">
        <type>transmission_interface/SimpleTransmission</type>
        <joint name="bar_C7/joint">
            <hardwareInterface>hardware_interface/EffortJointInterface</hardwareInterface>
        </joint>
        <actuator name="bar_C7/joint_motor">
            <mechanicalReduction>1</mechanicalReduction>
        </actuator>
    </transmission>
    <gazebo reference="bar_Cs4">
        <turnGravityOff>false</turnGravityOff>
        <selfCollide>true</selfCollide>
        <!-- TODO material -->
        <!-- <material>chordophones/OakWood</material> -->
        <mu1>50.0</mu1>
        <mu2>50.0</mu2>
        <kp>1000000.0</kp>
        <kd>1.0</kd>
    </gazebo>
    <link name="bar_Cs4">
        <inertial>
            <mass value="0.03" />
            <origin rpy="0 0 0" xyz="0 0 0" />
            <inertia ixx="0.01" ixy="0" ixz="0" iyy="0.01" iyz="0" izz="0.01" />
        </inertial>
        <visual>
            <origin rpy="0 0 0" xyz="0 0 -0.00925" />
            <geometry>
                <box size="0.314 0.0323 0.0185" />
            </geometry>
            <!-- TODO material -->
            <!-- <material name="oak_wood" /> -->
            <material name="marimba_key" />
        </visual>
        <collision>
            <origin rpy="0 0 0" xyz="0 0 -0.00925" />
            <geometry>
                <box size="0.314 0.0323 0.0185" />
            </geometry>
        </collision>
    </link>
    <joint name="bar_Cs4/joint" type="fixed">
        <origin rpy="0 0 0" xyz="-0.21 -0.395 0.0669" />
        <parent link="body_top" />
        <child link="bar_Cs4" />
    </joint>
    <transmission name="bar_Cs4/joint_transmission">
        <type>transmission_interface/SimpleTransmission</type>
        <joint name="bar_Cs4/joint">
            <hardwareInterface>hardware_interface/EffortJointInterface</hardwareInterface>
        </joint>
        <actuator name="bar_Cs4/joint_motor">
            <mechanicalReduction>1</mechanicalReduction>
        </actuator>
    </transmission>
    <gazebo reference="bar_Ds4">
        <turnGravityOff>false</turnGravityOff>
        <selfCollide>true</selfCollide>
        <!-- TODO material -->
        <!-- <material>chordophones/OakWood</material> -->
        <mu1>50.0</mu1>
        <mu2>50.0</mu2>
        <kp>1000000.0</kp>
        <kd>1.0</kd>
    </gazebo>
    <link name="bar_Ds4">
        <inertial>
            <mass value="0.03" />
            <origin rpy="0 0 0" xyz="0 0 0" />
            <inertia ixx="0.01" ixy="0" ixz="0" iyy="0.01" iyz="0" izz="0.01" />
        </inertial>
        <visual>
            <origin rpy="0 0 0" xyz="0 0 -0.00925" />
            <geometry>
                <box size="0.30755 0.0323 0.0185" />
            </geometry>
            <!-- TODO material -->
            <!-- <material name="oak_wood" /> -->
            <material name="marimba_key" />
        </visual>
        <collision>
            <origin rpy="0 0 0" xyz="0 0 -0.00925" />
            <geometry>
                <box size="0.30755 0.0323 0.0185" />
            </geometry>
        </collision>
    </link>
    <joint name="bar_Ds4/joint" type="fixed">
        <origin rpy="0 0 0" xyz="-0.20716199999999999 -0.3552 0.0669" />
        <parent link="body_top" />
        <child link="bar_Ds4" />
    </joint>
    <transmission name="bar_Ds4/joint_transmission">
        <type>transmission_interface/SimpleTransmission</type>
        <joint name="bar_Ds4/joint">
            <hardwareInterface>hardware_interface/EffortJointInterface</hardwareInterface>
        </joint>
        <actuator name="bar_Ds4/joint_motor">
            <mechanicalReduction>1</mechanicalReduction>
        </actuator>
    </transmission>
    <gazebo reference="bar_Fs4">
        <turnGravityOff>false</turnGravityOff>
        <selfCollide>true</selfCollide>
        <!-- TODO material -->
        <!-- <material>chordophones/OakWood</material> -->
        <mu1>50.0</mu1>
        <mu2>50.0</mu2>
        <kp>1000000.0</kp>
        <kd>1.0</kd>
    </gazebo>
    <link name="bar_Fs4">
        <inertial>
            <mass value="0.03" />
            <origin rpy="0 0 0" xyz="0 0 0" />
            <inertia ixx="0.01" ixy="0" ixz="0" iyy="0.01" iyz="0" izz="0.01" />
        </inertial>
        <visual>
            <origin rpy="0 0 0" xyz="0 0 -0.00925" />
            <geometry>
                <box size="0.29465 0.0323 0.0185" />
            </geometry>
            <!-- TODO material -->
            <!-- <material name="oak_wood" /> -->
            <material name="marimba_key" />
        </visual>
        <collision>
            <origin rpy="0 0 0" xyz="0 0 -0.00925" />
            <geometry>
                <box size="0.29465 0.0323 0.0185" />
            </geometry>
        </collision>
    </link>
    <joint name="bar_Fs4/joint" type="fixed">
        <origin rpy="0 0 0" xyz="-0.201486 -0.2756 0.0669" />
        <parent link="body_top" />
        <child link="bar_Fs4" />
    </joint>
    <transmission name="bar_Fs4/joint_transmission">
        <type>transmission_interface/SimpleTransmission</type>
        <joint name="bar_Fs4/joint">
            <hardwareInterface>hardware_interface/EffortJointInterface</hardwareInterface>
        </joint>
        <actuator name="bar_Fs4/joint_motor">
            <mechanicalReduction>1</mechanicalReduction>
        </actuator>
    </transmission>
    <gazebo reference="bar_Gs4">
        <turnGravityOff>false</turnGravityOff>
        <selfCollide>true</selfCollide>
        <!-- TODO material -->
        <!-- <material>chordophones/OakWood</material> -->
        <mu1>50.0</mu1>
        <mu2>50.0</mu2>
        <kp>1000000.0</kp>
        <kd>1.0</kd>
    </gazebo>
    <link name="bar_Gs4">
        <inertial>
            <mass value="0.03" />
            <origin rpy="0 0 0" xyz="0 0 0" />
            <inertia ixx="0.01" ixy="0" ixz="0" iyy="0.01" iyz="0" izz="0.01" />
        </inertial>
        <visual>
            <origin rpy="0 0 0" xyz="0 0 -0.00925" />
            <geometry>
                <box size="0.2882 0.0323 0.0185" />
            </geometry>
            <!-- TODO material -->
            <!-- <material name="oak_wood" /> -->
            <material name="marimba_key" />
        </visual>
        <collision>
            <origin rpy="0 0 0" xyz="0 0 -0.00925" />
            <geometry>
                <box size="0.2882 0.0323 0.0185" />
            </geometry>
        </collision>
    </link>
    <joint name="bar_Gs4/joint" type="fixed">
        <origin rpy="0 0 0" xyz="-0.198648 -0.2358 0.0669" />
        <parent link="body_top" />
        <child link="bar_Gs4" />
    </joint>
    <transmission name="bar_Gs4/joint_transmission">
        <type>transmission_interface/SimpleTransmission</type>
        <joint name="bar_Gs4/joint">
            <hardwareInterface>hardware_interface/EffortJointInterface</hardwareInterface>
        </joint>
        <actuator name="bar_Gs4/joint_motor">
            <mechanicalReduction>1</mechanicalReduction>
        </actuator>
    </transmission>
    <gazebo reference="bar_As4">
        <turnGravityOff>false</turnGravityOff>
        <selfCollide>true</selfCollide>
        <!-- TODO material -->
        <!-- <material>chordophones/OakWood</material> -->
        <mu1>50.0</mu1>
        <mu2>50.0</mu2>
        <kp>1000000.0</kp>
        <kd>1.0</kd>
    </gazebo>
    <link name="bar_As4">
        <inertial>
            <mass value="0.03" />
            <origin rpy="0 0 0" xyz="0 0 0" />
            <inertia ixx="0.01" ixy="0" ixz="0" iyy="0.01" iyz="0" izz="0.01" />
        </inertial>
        <visual>
            <origin rpy="0 0 0" xyz="0 0 -0.00925" />
            <geometry>
                <box size="0.28175 0.0323 0.0185" />
            </geometry>
            <!-- TODO material -->
            <!-- <material name="oak_wood" /> -->
            <material name="marimba_key" />
        </visual>
        <collision>
            <origin rpy="0 0 0" xyz="0 0 -0.00925" />
            <geometry>
                <box size="0.28175 0.0323 0.0185" />
            </geometry>
        </collision>
    </link>
    <joint name="bar_As4/joint" type="fixed">
        <origin rpy="0 0 0" xyz="-0.19580999999999998 -0.196 0.0669" />
        <parent link="body_top" />
        <child link="bar_As4" />
    </joint>
    <transmission name="bar_As4/joint_transmission">
        <type>transmission_interface/SimpleTransmission</type>
        <joint name="bar_As4/joint">
            <hardwareInterface>hardware_interface/EffortJointInterface</hardwareInterface>
        </joint>
        <actuator name="bar_As4/joint_motor">
            <mechanicalReduction>1</mechanicalReduction>
        </actuator>
    </transmission>
    <gazebo reference="bar_Cs5">
        <turnGravityOff>false</turnGravityOff>
        <selfCollide>true</selfCollide>
        <!-- TODO material -->
        <!-- <material>chordophones/OakWood</material> -->
        <mu1>50.0</mu1>
        <mu2>50.0</mu2>
        <kp>1000000.0</kp>
        <kd>1.0</kd>
    </gazebo>
    <link name="bar_Cs5">
        <inertial>
            <mass value="0.03" />
            <origin rpy="0 0 0" xyz="0 0 0" />
            <inertia ixx="0.01" ixy="0" ixz="0" iyy="0.01" iyz="0" izz="0.01" />
        </inertial>
        <visual>
            <origin rpy="0 0 0" xyz="0 0 -0.00925" />
            <geometry>
                <box size="0.26885000000000003 0.0323 0.0185" />
            </geometry>
            <!-- TODO material -->
            <!-- <material name="oak_wood" /> -->
            <material name="marimba_key" />
        </visual>
        <collision>
            <origin rpy="0 0 0" xyz="0 0 -0.00925" />
            <geometry>
                <box size="0.26885000000000003 0.0323 0.0185" />
            </geometry>
        </collision>
    </link>
    <joint name="bar_Cs5/joint" type="fixed">
        <origin rpy="0 0 0" xyz="-0.190134 -0.1164 0.0669" />
        <parent link="body_top" />
        <child link="bar_Cs5" />
    </joint>
    <transmission name="bar_Cs5/joint_transmission">
        <type>transmission_interface/SimpleTransmission</type>
        <joint name="bar_Cs5/joint">
            <hardwareInterface>hardware_interface/EffortJointInterface</hardwareInterface>
        </joint>
        <actuator name="bar_Cs5/joint_motor">
            <mechanicalReduction>1</mechanicalReduction>
        </actuator>
    </transmission>
    <gazebo reference="bar_Ds5">
        <turnGravityOff>false</turnGravityOff>
        <selfCollide>true</selfCollide>
        <!-- TODO material -->
        <!-- <material>chordophones/OakWood</material> -->
        <mu1>50.0</mu1>
        <mu2>50.0</mu2>
        <kp>1000000.0</kp>
        <kd>1.0</kd>
    </gazebo>
    <link name="bar_Ds5">
        <inertial>
            <mass value="0.03" />
            <origin rpy="0 0 0" xyz="0 0 0" />
            <inertia ixx="0.01" ixy="0" ixz="0" iyy="0.01" iyz="0" izz="0.01" />
        </inertial>
        <visual>
            <origin rpy="0 0 0" xyz="0 0 -0.00925" />
            <geometry>
                <box size="0.26239999999999997 0.0323 0.0185" />
            </geometry>
            <!-- TODO material -->
            <!-- <material name="oak_wood" /> -->
            <material name="marimba_key" />
        </visual>
        <collision>
            <origin rpy="0 0 0" xyz="0 0 -0.00925" />
            <geometry>
                <box size="0.26239999999999997 0.0323 0.0185" />
            </geometry>
        </collision>
    </link>
    <joint name="bar_Ds5/joint" type="fixed">
        <origin rpy="0 0 0" xyz="-0.187296 -0.0766 0.0669" />
        <parent link="body_top" />
        <child link="bar_Ds5" />
    </joint>
    <transmission name="bar_Ds5/joint_transmission">
        <type>transmission_interface/SimpleTransmission</type>
        <joint name="bar_Ds5/joint">
            <hardwareInterface>hardware_interface/EffortJointInterface</hardwareInterface>
        </joint>
        <actuator name="bar_Ds5/joint_motor">
            <mechanicalReduction>1</mechanicalReduction>
        </actuator>
    </transmission>
    <gazebo reference="bar_Fs5">
        <turnGravityOff>false</turnGravityOff>
        <selfCollide>true</selfCollide>
        <!-- TODO material -->
        <!-- <material>chordophones/OakWood</material> -->
        <mu1>50.0</mu1>
        <mu2>50.0</mu2>
        <kp>1000000.0</kp>
        <kd>1.0</kd>
    </gazebo>
    <link name="bar_Fs5">
        <inertial>
            <mass value="0.03" />
            <origin rpy="0 0 0" xyz="0 0 0" />
            <inertia ixx="0.01" ixy="0" ixz="0" iyy="0.01" iyz="0" izz="0.01" />
        </inertial>
        <visual>
            <origin rpy="0 0 0" xyz="0 0 -0.00925" />
            <geometry>
                <box size="0.2495 0.0323 0.0185" />
            </geometry>
            <!-- TODO material -->
            <!-- <material name="oak_wood" /> -->
            <material name="marimba_key" />
        </visual>
        <collision>
            <origin rpy="0 0 0" xyz="0 0 -0.00925" />
            <geometry>
                <box size="0.2495 0.0323 0.0185" />
            </geometry>
        </collision>
    </link>
    <joint name="bar_Fs5/joint" type="fixed">
        <origin rpy="0 0 0" xyz="-0.18162 0.0030000000000000027 0.0669" />
        <parent link="body_top" />
        <child link="bar_Fs5" />
    </joint>
    <transmission name="bar_Fs5/joint_transmission">
        <type>transmission_interface/SimpleTransmission</type>
        <joint name="bar_Fs5/joint">
            <hardwareInterface>hardware_interface/EffortJointInterface</hardwareInterface>
        </joint>
        <actuator name="bar_Fs5/joint_motor">
            <mechanicalReduction>1</mechanicalReduction>
        </actuator>
    </transmission>
    <gazebo reference="bar_Gs5">
        <turnGravityOff>false</turnGravityOff>
        <selfCollide>true</selfCollide>
        <!-- TODO material -->
        <!-- <material>chordophones/OakWood</material> -->
        <mu1>50.0</mu1>
        <mu2>50.0</mu2>
        <kp>1000000.0</kp>
        <kd>1.0</kd>
    </gazebo>
    <link name="bar_Gs5">
        <inertial>
            <mass value="0.03" />
            <origin rpy="0 0 0" xyz="0 0 0" />
            <inertia ixx="0.01" ixy="0" ixz="0" iyy="0.01" iyz="0" izz="0.01" />
        </inertial>
        <visual>
            <origin rpy="0 0 0" xyz="0 0 -0.00925" />
            <geometry>
                <box size="0.24305 0.0323 0.0185" />
            </geometry>
            <!-- TODO material -->
            <!-- <material name="oak_wood" /> -->
            <material name="marimba_key" />
        </visual>
        <collision>
            <origin rpy="0 0 0" xyz="0 0 -0.00925" />
            <geometry>
                <box size="0.24305 0.0323 0.0185" />
            </geometry>
        </collision>
    </link>
    <joint name="bar_Gs5/joint" type="fixed">
        <origin rpy="0 0 0" xyz="-0.178782 0.042800000000000005 0.0669" />
        <parent link="body_top" />
        <child link="bar_Gs5" />
    </joint>
    <transmission name="bar_Gs5/joint_transmission">
        <type>transmission_interface/SimpleTransmission</type>
        <joint name="bar_Gs5/joint">
            <hardwareInterface>hardware_interface/EffortJointInterface</hardwareInterface>
        </joint>
        <actuator name="bar_Gs5/joint_motor">
            <mechanicalReduction>1</mechanicalReduction>
        </actuator>
    </transmission>
    <gazebo reference="bar_As5">
        <turnGravityOff>false</turnGravityOff>
        <selfCollide>true</selfCollide>
        <!-- TODO material -->
        <!-- <material>chordophones/OakWood</material> -->
        <mu1>50.0</mu1>
        <mu2>50.0</mu2>
        <kp>1000000.0</kp>
        <kd>1.0</kd>
    </gazebo>
    <link name="bar_As5">
        <inertial>
            <mass value="0.03" />
            <origin rpy="0 0 0" xyz="0 0 0" />
            <inertia ixx="0.01" ixy="0" ixz="0" iyy="0.01" iyz="0" izz="0.01" />
        </inertial>
        <visual>
            <origin rpy="0 0 0" xyz="0 0 -0.00925" />
            <geometry>
                <box size="0.2366 0.0323 0.0185" />
            </geometry>
            <!-- TODO material -->
            <!-- <material name="oak_wood" /> -->
            <material name="marimba_key" />
        </visual>
        <collision>
            <origin rpy="0 0 0" xyz="0 0 -0.00925" />
            <geometry>
                <box size="0.2366 0.0323 0.0185" />
            </geometry>
        </collision>
    </link>
    <joint name="bar_As5/joint" type="fixed">
        <origin rpy="0 0 0" xyz="-0.175944 0.0826 0.0669" />
        <parent link="body_top" />
        <child link="bar_As5" />
    </joint>
    <transmission name="bar_As5/joint_transmission">
        <type>transmission_interface/SimpleTransmission</type>
        <joint name="bar_As5/joint">
            <hardwareInterface>hardware_interface/EffortJointInterface</hardwareInterface>
        </joint>
        <actuator name="bar_As5/joint_motor">
            <mechanicalReduction>1</mechanicalReduction>
        </actuator>
    </transmission>
    <gazebo reference="bar_Cs6">
        <turnGravityOff>false</turnGravityOff>
        <selfCollide>true</selfCollide>
        <!-- TODO material -->
        <!-- <material>chordophones/OakWood</material> -->
        <mu1>50.0</mu1>
        <mu2>50.0</mu2>
        <kp>1000000.0</kp>
        <kd>1.0</kd>
    </gazebo>
    <link name="bar_Cs6">
        <inertial>
            <mass value="0.03" />
            <origin rpy="0 0 0" xyz="0 0 0" />
            <inertia ixx="0.01" ixy="0" ixz="0" iyy="0.01" iyz="0" izz="0.01" />
        </inertial>
        <visual>
            <origin rpy="0 0 0" xyz="0 0 -0.00925" />
            <geometry>
                <box size="0.2237 0.0323 0.0185" />
            </geometry>
            <!-- TODO material -->
            <!-- <material name="oak_wood" /> -->
            <material name="marimba_key" />
        </visual>
        <collision>
            <origin rpy="0 0 0" xyz="0 0 -0.00925" />
            <geometry>
                <box size="0.2237 0.0323 0.0185" />
            </geometry>
        </collision>
    </link>
    <joint name="bar_Cs6/joint" type="fixed">
        <origin rpy="0 0 0" xyz="-0.17026799999999997 0.1622 0.0669" />
        <parent link="body_top" />
        <child link="bar_Cs6" />
    </joint>
    <transmission name="bar_Cs6/joint_transmission">
        <type>transmission_interface/SimpleTransmission</type>
        <joint name="bar_Cs6/joint">
            <hardwareInterface>hardware_interface/EffortJointInterface</hardwareInterface>
        </joint>
        <actuator name="bar_Cs6/joint_motor">
            <mechanicalReduction>1</mechanicalReduction>
        </actuator>
    </transmission>
    <gazebo reference="bar_Ds6">
        <turnGravityOff>false</turnGravityOff>
        <selfCollide>true</selfCollide>
        <!-- TODO material -->
        <!-- <material>chordophones/OakWood</material> -->
        <mu1>50.0</mu1>
        <mu2>50.0</mu2>
        <kp>1000000.0</kp>
        <kd>1.0</kd>
    </gazebo>
    <link name="bar_Ds6">
        <inertial>
            <mass value="0.03" />
            <origin rpy="0 0 0" xyz="0 0 0" />
            <inertia ixx="0.01" ixy="0" ixz="0" iyy="0.01" iyz="0" izz="0.01" />
        </inertial>
        <visual>
            <origin rpy="0 0 0" xyz="0 0 -0.00925" />
            <geometry>
                <box size="0.21725 0.0323 0.0185" />
            </geometry>
            <!-- TODO material -->
            <!-- <material name="oak_wood" /> -->
            <material name="marimba_key" />
        </visual>
        <collision>
            <origin rpy="0 0 0" xyz="0 0 -0.00925" />
            <geometry>
                <box size="0.21725 0.0323 0.0185" />
            </geometry>
        </collision>
    </link>
    <joint name="bar_Ds6/joint" type="fixed">
        <origin rpy="0 0 0" xyz="-0.16743 0.20199999999999996 0.0669" />
        <parent link="body_top" />
        <child link="bar_Ds6" />
    </joint>
    <transmission name="bar_Ds6/joint_transmission">
        <type>transmission_interface/SimpleTransmission</type>
        <joint name="bar_Ds6/joint">
            <hardwareInterface>hardware_interface/EffortJointInterface</hardwareInterface>
        </joint>
        <actuator name="bar_Ds6/joint_motor">
            <mechanicalReduction>1</mechanicalReduction>
        </actuator>
    </transmission>
    <gazebo reference="bar_Fs6">
        <turnGravityOff>false</turnGravityOff>
        <selfCollide>true</selfCollide>
        <!-- TODO material -->
        <!-- <material>chordophones/OakWood</material> -->
        <mu1>50.0</mu1>
        <mu2>50.0</mu2>
        <kp>1000000.0</kp>
        <kd>1.0</kd>
    </gazebo>
    <link name="bar_Fs6">
        <inertial>
            <mass value="0.03" />
            <origin rpy="0 0 0" xyz="0 0 0" />
            <inertia ixx="0.01" ixy="0" ixz="0" iyy="0.01" iyz="0" izz="0.01" />
        </inertial>
        <visual>
            <origin rpy="0 0 0" xyz="0 0 -0.00925" />
            <geometry>
                <box size="0.20435 0.0323 0.0185" />
            </geometry>
            <!-- TODO material -->
            <!-- <material name="oak_wood" /> -->
            <material name="marimba_key" />
        </visual>
        <collision>
            <origin rpy="0 0 0" xyz="0 0 -0.00925" />
            <geometry>
                <box size="0.20435 0.0323 0.0185" />
            </geometry>
        </collision>
    </link>
    <joint name="bar_Fs6/joint" type="fixed">
        <origin rpy="0 0 0" xyz="-0.16175399999999998 0.2816000000000001 0.0669" />
        <parent link="body_top" />
        <child link="bar_Fs6" />
    </joint>
    <transmission name="bar_Fs6/joint_transmission">
        <type>transmission_interface/SimpleTransmission</type>
        <joint name="bar_Fs6/joint">
            <hardwareInterface>hardware_interface/EffortJointInterface</hardwareInterface>
        </joint>
        <actuator name="bar_Fs6/joint_motor">
            <mechanicalReduction>1</mechanicalReduction>
        </actuator>
    </transmission>
    <gazebo reference="bar_Gs6">
        <turnGravityOff>false</turnGravityOff>
        <selfCollide>true</selfCollide>
        <!-- TODO material -->
        <!-- <material>chordophones/OakWood</material> -->
        <mu1>50.0</mu1>
        <mu2>50.0</mu2>
        <kp>1000000.0</kp>
        <kd>1.0</kd>
    </gazebo>
    <link name="bar_Gs6">
        <inertial>
            <mass value="0.03" />
            <origin rpy="0 0 0" xyz="0 0 0" />
            <inertia ixx="0.01" ixy="0" ixz="0" iyy="0.01" iyz="0" izz="0.01" />
        </inertial>
        <visual>
            <origin rpy="0 0 0" xyz="0 0 -0.00925" />
            <geometry>
                <box size="0.1979 0.0323 0.0185" />
            </geometry>
            <!-- TODO material -->
            <!-- <material name="oak_wood" /> -->
            <material name="marimba_key" />
        </visual>
        <collision>
            <origin rpy="0 0 0" xyz="0 0 -0.00925" />
            <geometry>
                <box size="0.1979 0.0323 0.0185" />
            </geometry>
        </collision>
    </link>
    <joint name="bar_Gs6/joint" type="fixed">
        <origin rpy="0 0 0" xyz="-0.158916 0.3214 0.0669" />
        <parent link="body_top" />
        <child link="bar_Gs6" />
    </joint>
    <transmission name="bar_Gs6/joint_transmission">
        <type>transmission_interface/SimpleTransmission</type>
        <joint name="bar_Gs6/joint">
            <hardwareInterface>hardware_interface/EffortJointInterface</hardwareInterface>
        </joint>
        <actuator name="bar_Gs6/joint_motor">
            <mechanicalReduction>1</mechanicalReduction>
        </actuator>
    </transmission>
    <gazebo reference="bar_As6">
        <turnGravityOff>false</turnGravityOff>
        <selfCollide>true</selfCollide>
        <!-- TODO material -->
        <!-- <material>chordophones/OakWood</material> -->
        <mu1>50.0</mu1>
        <mu2>50.0</mu2>
        <kp>1000000.0</kp>
        <kd>1.0</kd>
    </gazebo>
    <link name="bar_As6">
        <inertial>
            <mass value="0.03" />
            <origin rpy="0 0 0" xyz="0 0 0" />
            <inertia ixx="0.01" ixy="0" ixz="0" iyy="0.01" iyz="0" izz="0.01" />
        </inertial>
        <visual>
            <origin rpy="0 0 0" xyz="0 0 -0.00925" />
            <geometry>
                <box size="0.19145 0.0323 0.0185" />
            </geometry>
            <!-- TODO material -->
            <!-- <material name="oak_wood" /> -->
            <material name="marimba_key" />
        </visual>
        <collision>
            <origin rpy="0 0 0" xyz="0 0 -0.00925" />
            <geometry>
                <box size="0.19145 0.0323 0.0185" />
            </geometry>
        </collision>
    </link>
    <joint name="bar_As6/joint" type="fixed">
        <origin rpy="0 0 0" xyz="-0.156078 0.36119999999999997 0.0669" />
        <parent link="body_top" />
        <child link="bar_As6" />
    </joint>
    <transmission name="bar_As6/joint_transmission">
        <type>transmission_interface/SimpleTransmission</type>
        <joint name="bar_As6/joint">
            <hardwareInterface>hardware_interface/EffortJointInterface</hardwareInterface>
        </joint>
        <actuator name="bar_As6/joint_motor">
            <mechanicalReduction>1</mechanicalReduction>
        </actuator>
    </transmission>
    <link name="ur5_base_link">
        <visual>
            <geometry>
                <mesh filename="package://ur_description/meshes/ur5/visual/base.dae" />
            </geometry>
            <material name="LightGrey">
                <color rgba="0.7 0.7 0.7 1.0" />
            </material>
        </visual>
        <collision>
            <geometry>
                <mesh filename="package://ur_description/meshes/ur5/collision/base.stl" />
            </geometry>
        </collision>
        <inertial>
            <mass value="4.0" />
            <origin rpy="0 0 0" xyz="0.0 0.0 0.0" />
            <inertia ixx="0.00443333156" ixy="0.0" ixz="0.0" iyy="0.00443333156" iyz="0.0" izz="0.0072" />
        </inertial>
    </link>
    <joint name="ur5_shoulder_pan_joint" type="revolute">
        <parent link="ur5_base_link" />
        <child link="ur5_shoulder_link" />
        <origin rpy="0.0 0.0 0.0" xyz="0.0 0.0 0.089159" />
        <axis xyz="0 0 1" />
        <limit effort="150.0" lower="-6.2811853" upper="6.2811853" velocity="3.15" />
        <dynamics damping="0.0" friction="0.0" />
    </joint>
    <link name="ur5_shoulder_link">
        <visual>
            <geometry>
                <mesh filename="package://ur_description/meshes/ur5/visual/shoulder.dae" />
            </geometry>
            <material name="LightGrey">
                <color rgba="0.7 0.7 0.7 1.0" />
            </material>
        </visual>
        <collision>
            <geometry>
                <mesh filename="package://ur_description/meshes/ur5/collision/shoulder.stl" />
            </geometry>
        </collision>
        <inertial>
            <mass value="3.7" />
            <origin rpy="0 0 0" xyz="0.0 0.0 0.0" />
            <inertia ixx="0.010267495893" ixy="0.0" ixz="0.0" iyy="0.010267495893" iyz="0.0" izz="0.00666" />
        </inertial>
    </link>
    <joint name="ur5_shoulder_lift_joint" type="revolute">
        <parent link="ur5_shoulder_link" />
        <child link="ur5_upper_arm_link" />
        <origin rpy="0.0 1.5707963267948966 0.0" xyz="0.0 0.13585 0.0" />
        <axis xyz="0 1 0" />
        <limit effort="150.0" lower="-6.2811853" upper="6.2811853" velocity="3.15" />
        <dynamics damping="0.0" friction="0.0" />
    </joint>
    <link name="ur5_upper_arm_link">
        <visual>
            <geometry>
                <mesh filename="package://ur_description/meshes/ur5/visual/upperarm.dae" />
            </geometry>
            <material name="LightGrey">
                <color rgba="0.7 0.7 0.7 1.0" />
            </material>
        </visual>
        <collision>
            <geometry>
                <mesh filename="package://ur_description/meshes/ur5/collision/upperarm.stl" />
            </geometry>
        </collision>
        <inertial>
            <mass value="8.393" />
            <origin rpy="0 0 0" xyz="0.0 0.0 0.28" />
            <inertia ixx="0.22689067591036005" ixy="0.0" ixz="0.0" iyy="0.22689067591036005" iyz="0.0" izz="0.0151074" />
        </inertial>
    </link>
    <joint name="ur5_elbow_joint" type="revolute">
        <parent link="ur5_upper_arm_link" />
        <child link="ur5_forearm_link" />
        <origin rpy="0.0 0.0 0.0" xyz="0.0 -0.1197 0.425" />
        <axis xyz="0 1 0" />
        <limit effort="150.0" lower="-3.1415926" upper="3.1415926" velocity="3.15" />
        <dynamics damping="0.0" friction="0.0" />
    </joint>
    <link name="ur5_forearm_link">
        <visual>
            <geometry>
                <mesh filename="package://ur_description/meshes/ur5/visual/forearm.dae" />
            </geometry>
            <material name="LightGrey">
                <color rgba="0.7 0.7 0.7 1.0" />
            </material>
        </visual>
        <collision>
            <geometry>
                <mesh filename="package://ur_description/meshes/ur5/collision/forearm.stl" />
            </geometry>
        </collision>
        <inertial>
            <mass value="2.275" />
            <origin rpy="0 0 0" xyz="0.0 0.0 0.25" />
            <inertia ixx="0.04944331355599999" ixy="0.0" ixz="0.0" iyy="0.04944331355599999" iyz="0.0" izz="0.004095" />
        </inertial>
    </link>
    <joint name="ur5_wrist_1_joint" type="revolute">
        <parent link="ur5_forearm_link" />
        <child link="ur5_wrist_1_link" />
        <origin rpy="0.0 1.5707963267948966 0.0" xyz="0.0 0.0 0.39225" />
        <axis xyz="0 1 0" />
        <limit effort="28.0" lower="-6.2811853" upper="6.2811853" velocity="3.2" />
        <dynamics damping="0.0" friction="0.0" />
    </joint>
    <link name="ur5_wrist_1_link">
        <visual>
            <geometry>
                <mesh filename="package://ur_description/meshes/ur5/visual/wrist1.dae" />
            </geometry>
            <material name="LightGrey">
                <color rgba="0.7 0.7 0.7 1.0" />
            </material>
        </visual>
        <collision>
            <geometry>
                <mesh filename="package://ur_description/meshes/ur5/collision/wrist1.stl" />
            </geometry>
        </collision>
        <inertial>
            <mass value="1.219" />
            <origin rpy="0 0 0" xyz="0.0 0.0 0.0" />
            <inertia ixx="0.11117275553087999" ixy="0.0" ixz="0.0" iyy="0.11117275553087999" iyz="0.0" izz="0.21942" />
        </inertial>
    </link>
    <joint name="ur5_wrist_2_joint" type="revolute">
        <parent link="ur5_wrist_1_link" />
        <child link="ur5_wrist_2_link" />
        <origin rpy="0.0 0.0 0.0" xyz="0.0 0.093 0.0" />
        <axis xyz="0 0 1" />
        <limit effort="28.0" lower="-3.1415926" upper="3.1415926" velocity="3.2" />
        <dynamics damping="0.0" friction="0.0" />
    </joint>
    <link name="ur5_wrist_2_link">
        <visual>
            <geometry>
                <mesh filename="package://tams_ur5_description/meshes/ur5/visual/wrist2_rounded.dae" />
            </geometry>
            <material name="LightGrey">
                <color rgba="0.7 0.7 0.7 1.0" />
            </material>
        </visual>
        <collision>
            <geometry>
                <mesh filename="package://tams_ur5_description/meshes/ur5/collision/wrist2_rounded.stl" />
            </geometry>
        </collision>
        <inertial>
            <mass value="1.219" />
            <origin rpy="0 0 0" xyz="0.0 0.0 0.0" />
            <inertia ixx="0.11117275553087999" ixy="0.0" ixz="0.0" iyy="0.11117275553087999" iyz="0.0" izz="0.21942" />
        </inertial>
    </link>
    <joint name="ur5_wrist_3_joint" type="revolute">
        <parent link="ur5_wrist_2_link" />
        <child link="ur5_wrist_3_link" />
        <origin rpy="0.0 0.0 0.0" xyz="0.0 0.0 0.09465" />
        <axis xyz="0 1 0" />
        <limit effort="28.0" lower="-6.2811853" upper="6.2811853" velocity="3.2" />
        <dynamics damping="0.0" friction="0.0" />
    </joint>
    <link name="ur5_wrist_3_link">
        <visual>
            <geometry>
                <mesh filename="package://ur_description/meshes/ur5/visual/wrist3.dae" />
            </geometry>
            <material name="LightGrey">
                <color rgba="0.7 0.7 0.7 1.0" />
            </material>
        </visual>
        <collision>
            <geometry>
                <mesh filename="package://ur_description/meshes/ur5/collision/wrist3.stl" />
            </geometry>
        </collision>
        <inertial>
            <mass value="0.1879" />
            <origin rpy="0 0 0" xyz="0.0 0.0 0.0" />
            <inertia ixx="0.017136473145408" ixy="0.0" ixz="0.0" iyy="0.017136473145408" iyz="0.0" izz="0.033822" />
        </inertial>
    </link>
    <joint name="ur5_ee_fixed_joint" type="fixed">
        <parent link="ur5_wrist_3_link" />
        <child link="ur5_ee_link" />
        <origin rpy="0.0 0.0 1.5707963267948966" xyz="0.0 0.0823 0.0" />
    </joint>
    <link name="ur5_ee_link">
        <collision>
            <geometry>
                <box size="0.01 0.01 0.01" />
            </geometry>
            <origin rpy="0 0 0" xyz="-0.01 0 0" />
        </collision>
        <inertial>
            <mass value="0.1" />
            <origin xyz="0 0 0" rpy="0 0 0" />
            <inertia ixx="0.03" iyy="0.03" izz="0.03" ixy="0.0" ixz="0.0" iyz="0.0" />
        </inertial>
    </link>
    <!-- fnh: we don't want these, and especially not hidden here 
    <xacro:ur_arm_transmission prefix="${prefix}"/>
    <xacro:ur_arm_gazebo prefix="${prefix}" />
    -->
    <!-- ROS base_link to UR 'Base' Coordinates transform -->
    <link name="ur5_base" />
    <joint name="ur5_base_link-base_fixed_joint" type="fixed">
        <!-- NOTE: this rotation is only needed as long as base_link itself is
                 not corrected wrt the real robot (ie: rotated over 180
                 degrees)
      -->
        <origin rpy="0 0 -3.141592653589793" xyz="0 0 0" />
        <parent link="ur5_base_link" />
        <child link="ur5_base" />
    </joint>
    <!-- Frame coincident with all-zeros TCP on UR controller -->
    <link name="ur5_tool0" />
    <joint name="ur5_wrist_3_link-tool0_fixed_joint" type="fixed">
        <origin rpy="-1.5707963267948966 0 0" xyz="0 0.0823 0" />
        <parent link="ur5_wrist_3_link" />
        <child link="ur5_tool0" />
    </joint>
    <link name="ft_adapter">
        <!-- TODO values for inertial are not correct -->
        <inertial>
            <mass value="0.2" />
            <origin xyz="0.0 0.0 0.0" rpy="0 0 0" />
            <inertia ixx="0.002708332" ixy="0.0" ixz="0.0" iyy="0.000708333" iyz="0.0" izz="0.003333332" />
        </inertial>
        <visual>
            <origin rpy="0 0 0.0" xyz="0.0 0 0.0" />
            <geometry>
                <box size="0.088 0.088 0.009" />
            </geometry>
            <material name="gray">
                <color rgba="0.2 0.2 0.2 1" />
            </material>
        </visual>
        <collision>
            <origin rpy="0 0 0.0" xyz="0.0 0 0.0" />
            <geometry>
                <box size="0.088 0.088 0.009" />
            </geometry>
        </collision>
    </link>
    <joint name="ft_adapter_joint" type="fixed">
        <origin rpy="0.0 1.5707963267948966 0.0" xyz="0.0045 0.0 0.0" />
        <child link="ft_adapter" />
        <parent link="ur5_ee_link" />
    </joint>
    <!-- mount the fts to the robot -->
    <joint name="ft_fts_fix" type="fixed">
        <!--In most cases origin would be flange adapter plate: <origin xyz="0 0 0.009" rpy="0 0 0"/> /-->
        <origin rpy="0.0 -1.5707963267948966 3.141592653589793" xyz="0.009 0.0 0.0" />
        <parent link="ur5_ee_link" />
        <child link="ft_fts_robotside" />
    </joint>
    <link name="ft_fts_robotside">
        <inertial>
            <origin rpy="0 0 0" xyz="0 0 0.01875" />
            <mass value="0.65" />
            <inertia ixx="0.000661171875" ixy="0" ixz="0" iyy="0.000661171875" iyz="0" izz="0.00117" />
        </inertial>
        <visual>
            <origin rpy="0 0 0" xyz="0 0 0" />
            <geometry>
                <mesh filename="package://robotiq_ft_sensor/meshes/visual/robotiq_fts150.stl" />
            </geometry>
            <material name="black" />
        </visual>
        <collision>
            <origin rpy="0 0 0" xyz="0 0 0" />
            <geometry>
                <mesh filename="package://robotiq_ft_sensor/meshes/collision/robotiq_fts150.stl" />
            </geometry>
        </collision>
    </link>
    <!-- virtual measurement frame -->
    <joint name="ft_measurment_joint" type="fixed">
        <origin rpy="0 0 0" xyz="0 0 0.01625" />
        <parent link="ft_fts_robotside" />
        <child link="ft_robotiq_ft_frame_id" />
    </joint>
    <link name="ft_robotiq_ft_frame_id" />
    <!-- toolside frame -->
    <joint name="ft_toolside_joint" type="fixed">
        <origin rpy="0 0 0" xyz="0 0 0.0375" />
        <parent link="ft_fts_robotside" />
        <child link="ft_fts_toolside" />
    </joint>
    <link name="ft_fts_toolside" />
    <!-- tool0 frame -->
    <link name="tool0" />
    <joint name="ft_fts_toolside_tool0" type="fixed">
        <parent link="ft_fts_toolside" />
        <child link="tool0" />
        <origin rpy="0.0 -1.5707963267948966 0.0" xyz="0.0 0.0 0.0205" />
    </joint>
    <link name="s_model_adapter">
        <!-- TODO values for inertial are not correct -->
        <inertial>
            <mass value="0.2" />
            <origin xyz="0.0 0.0 0.0" rpy="0 0 0" />
            <inertia ixx="0.002708332" ixy="0.0" ixz="0.0" iyy="0.000708333" iyz="0.0" izz="0.003333332" />
        </inertial>
        <visual>
            <origin rpy="0 0 0.0" xyz="0.0 0 0.0" />
            <geometry>
                <cylinder length="0.035" radius="0.06" />
            </geometry>
            <material name="gray">
                <color rgba="0.2 0.2 0.2 1" />
            </material>
        </visual>
        <visual>
            <origin rpy="0 0 0.0" xyz="0.0725 0 0" />
            <geometry>
                <box size="0.035 0.035 0.035" />
            </geometry>
            <material name="gray">
                <color rgba="0.2 0.2 0.2 1" />
            </material>
        </visual>
        <collision>
            <origin rpy="0 0 0.0" xyz="0.0 0 0.0" />
            <geometry>
                <cylinder length="0.035" radius="0.06" />
            </geometry>
        </collision>
        <collision>
            <origin rpy="0 0 0.0" xyz="0.0725 0 0" />
            <geometry>
                <box size="0.035 0.035 0.035" />
            </geometry>
        </collision>
    </link>
    <joint name="s_model_adapter_joint" type="fixed">
        <origin rpy="0.0 0.0 0.0" xyz="0.0 0.0 0.015" />
        <child link="s_model_adapter" />
        <parent link="ft_fts_toolside" />
    </joint>
    <!-- link list -->
    <link name="s_model_finger_1_link_0">
        <visual>
            <origin rpy="0 0 0" xyz="0.020 0 0" />
            <geometry>
                <mesh filename="package://robotiq_3f_gripper_visualization/meshes/robotiq-3f-gripper_articulated/visual/link_0.dae" />
            </geometry>
            <material name="gray">
                <color rgba="0.2 0.2 0.2 1" />
            </material>
        </visual>
        <collision>
            <origin rpy="0 0 0" xyz="0.020 0 0" />
            <geometry>
                <mesh filename="package://robotiq_3f_gripper_visualization/meshes/robotiq-3f-gripper_articulated/collision/link_0.STL" />
            </geometry>
            <material name="yellow">
                <color rgba="0 1 1 1" />
            </material>
        </collision>
        <inertial>
            <origin rpy="0 0 0" xyz="0 0 0" />
            <mass value="0.05" />
            <inertia ixx="0.01" ixy="-0.00002" ixz="0.00001" iyy="0.0008" iyz="0" izz="0.001" />
        </inertial>
    </link>
    <link name="s_model_finger_1_link_1">
        <visual>
            <origin rpy="0 0 -0.52" xyz="0.050 -.028 0" />
            <geometry>
                <mesh filename="package://robotiq_3f_gripper_visualization/meshes/robotiq-3f-gripper_articulated/visual/link_1.dae" />
            </geometry>
            <material name="gray" />
        </visual>
        <collision>
            <origin rpy="0 0 -0.52" xyz="0.050 -.028 0" />
            <geometry>
                <mesh filename="package://robotiq_3f_gripper_visualization/meshes/robotiq-3f-gripper_articulated/collision/link_1.STL" />
            </geometry>
            <material name="yellow" />
        </collision>
        <inertial>
            <origin rpy="0 0 0" xyz="0 0 0" />
            <mass value="0.15" />
            <inertia ixx="0.001859" ixy="-0.000376" ixz="0.000028" iyy="0.012756" iyz="0" izz="0.0024" />
        </inertial>
    </link>
    <link name="s_model_finger_1_link_2">
        <!--
			NOTE: This link has an offset in the z-direction based on the models that were
			used to generate grap-it poses.  With the offset below the model appears visually
			correct, but it is suspect.
			-->
        <visual>
            <origin rpy="0 0 0" xyz="0.039 0 0.0075" />
            <geometry>
                <mesh filename="package://robotiq_3f_gripper_visualization/meshes/robotiq-3f-gripper_articulated/visual/link_2.dae" />
            </geometry>
            <material name="gray" />
        </visual>
        <collision>
            <origin rpy="0 0 0" xyz="0.039 0 0.0075" />
            <geometry>
                <mesh filename="package://robotiq_3f_gripper_visualization/meshes/robotiq-3f-gripper_articulated/collision/link_2.STL" />
            </geometry>
            <material name="yellow" />
        </collision>
        <inertial>
            <origin rpy="0 0 0" xyz="0 0 0" />
            <mass value="0.15" />
            <inertia ixx="0.001859" ixy="-0.000376" ixz="0.000028" iyy="0.012756" iyz="0" izz="0.0024" />
        </inertial>
    </link>
    <link name="s_model_finger_1_link_3">
        <visual>
            <origin rpy="0 0 0.52" xyz="0 0 0" />
            <geometry>
                <mesh filename="package://robotiq_3f_gripper_visualization/meshes/robotiq-3f-gripper_articulated/visual/link_3.dae" />
            </geometry>
            <material name="gray" />
        </visual>
        <collision>
            <origin rpy="0 0 0.52" xyz="0 0 0" />
            <geometry>
                <mesh filename="package://robotiq_3f_gripper_visualization/meshes/robotiq-3f-gripper_articulated/collision/link_3.STL" />
            </geometry>
            <material name="yellow" />
        </collision>
        <inertial>
            <origin rpy="0 0 0" xyz="0 0 0" />
            <mass value="0.05" />
            <inertia ixx="0.001239" ixy="-0.000251" ixz="0.000019" iyy="0.00085" iyz="0" izz="0.001632" />
        </inertial>
    </link>
    <!-- end of link list -->
    <!-- joint list -->
    <joint name="s_model_finger_1_joint_1" type="revolute">
        <parent link="s_model_finger_1_link_0" />
        <child link="s_model_finger_1_link_1" />
        <axis xyz="0 0 1" />
        <origin rpy="0 0 0" xyz="0.020 0 0" />
        <!-- fnh: velocity=100 is far too fast. We also want some damping for Gazebo -->
        <limit effort="100" lower="0.0495" upper="1.2218" velocity="1.23" />
        <dynamics damping="1" friction="0.1" />
    </joint>
    <joint name="s_model_finger_1_joint_2" type="revolute">
        <parent link="s_model_finger_1_link_1" />
        <child link="s_model_finger_1_link_2" />
        <axis xyz="0 0 1" />
        <origin rpy="0 0 -0.52" xyz="0.050 -.028 0" />
        <limit effort="100" lower="0.0" upper="1.5708" velocity="1.24" />
        <dynamics damping="1" friction="0.1" />
    </joint>
    <joint name="s_model_finger_1_joint_3" type="revolute">
        <parent link="s_model_finger_1_link_2" />
        <child link="s_model_finger_1_link_3" />
        <axis xyz="0 0 1" />
        <origin rpy="0 0 0" xyz="0.039 0 0" />
        <limit effort="100" lower="-1.2217" upper="-0.0523" velocity="1.25" />
        <dynamics damping="1" friction="0.1" />
    </joint>
    <!-- end of joint list -->
    <!-- link list -->
    <link name="s_model_finger_2_link_0">
        <visual>
            <origin rpy="0 0 0" xyz="0.020 0 0" />
            <geometry>
                <mesh filename="package://robotiq_3f_gripper_visualization/meshes/robotiq-3f-gripper_articulated/visual/link_0.dae" />
            </geometry>
            <material name="gray">
                <color rgba="0.2 0.2 0.2 1" />
            </material>
        </visual>
        <collision>
            <origin rpy="0 0 0" xyz="0.020 0 0" />
            <geometry>
                <mesh filename="package://robotiq_3f_gripper_visualization/meshes/robotiq-3f-gripper_articulated/collision/link_0.STL" />
            </geometry>
            <material name="yellow">
                <color rgba="0 1 1 1" />
            </material>
        </collision>
        <inertial>
            <origin rpy="0 0 0" xyz="0 0 0" />
            <mass value="0.05" />
            <inertia ixx="0.01" ixy="-0.00002" ixz="0.00001" iyy="0.0008" iyz="0" izz="0.001" />
        </inertial>
    </link>
    <link name="s_model_finger_2_link_1">
        <visual>
            <origin rpy="0 0 -0.52" xyz="0.050 -.028 0" />
            <geometry>
                <mesh filename="package://robotiq_3f_gripper_visualization/meshes/robotiq-3f-gripper_articulated/visual/link_1.dae" />
            </geometry>
            <material name="gray" />
        </visual>
        <collision>
            <origin rpy="0 0 -0.52" xyz="0.050 -.028 0" />
            <geometry>
                <mesh filename="package://robotiq_3f_gripper_visualization/meshes/robotiq-3f-gripper_articulated/collision/link_1.STL" />
            </geometry>
            <material name="yellow" />
        </collision>
        <inertial>
            <origin rpy="0 0 0" xyz="0 0 0" />
            <mass value="0.15" />
            <inertia ixx="0.001859" ixy="-0.000376" ixz="0.000028" iyy="0.012756" iyz="0" izz="0.0024" />
        </inertial>
    </link>
    <link name="s_model_finger_2_link_2">
        <!--
			NOTE: This link has an offset in the z-direction based on the models that were
			used to generate grap-it poses.  With the offset below the model appears visually
			correct, but it is suspect.
			-->
        <visual>
            <origin rpy="0 0 0" xyz="0.039 0 0.0075" />
            <geometry>
                <mesh filename="package://robotiq_3f_gripper_visualization/meshes/robotiq-3f-gripper_articulated/visual/link_2.dae" />
            </geometry>
            <material name="gray" />
        </visual>
        <collision>
            <origin rpy="0 0 0" xyz="0.039 0 0.0075" />
            <geometry>
                <mesh filename="package://robotiq_3f_gripper_visualization/meshes/robotiq-3f-gripper_articulated/collision/link_2.STL" />
            </geometry>
            <material name="yellow" />
        </collision>
        <inertial>
            <origin rpy="0 0 0" xyz="0 0 0" />
            <mass value="0.15" />
            <inertia ixx="0.001859" ixy="-0.000376" ixz="0.000028" iyy="0.012756" iyz="0" izz="0.0024" />
        </inertial>
    </link>
    <link name="s_model_finger_2_link_3">
        <visual>
            <origin rpy="0 0 0.52" xyz="0 0 0" />
            <geometry>
                <mesh filename="package://robotiq_3f_gripper_visualization/meshes/robotiq-3f-gripper_articulated/visual/link_3.dae" />
            </geometry>
            <material name="gray" />
        </visual>
        <collision>
            <origin rpy="0 0 0.52" xyz="0 0 0" />
            <geometry>
                <mesh filename="package://robotiq_3f_gripper_visualization/meshes/robotiq-3f-gripper_articulated/collision/link_3.STL" />
            </geometry>
            <material name="yellow" />
        </collision>
        <inertial>
            <origin rpy="0 0 0" xyz="0 0 0" />
            <mass value="0.05" />
            <inertia ixx="0.001239" ixy="-0.000251" ixz="0.000019" iyy="0.00085" iyz="0" izz="0.001632" />
        </inertial>
    </link>
    <!-- end of link list -->
    <!-- joint list -->
    <joint name="s_model_finger_2_joint_1" type="revolute">
        <parent link="s_model_finger_2_link_0" />
        <child link="s_model_finger_2_link_1" />
        <axis xyz="0 0 1" />
        <origin rpy="0 0 0" xyz="0.020 0 0" />
        <!-- fnh: velocity=100 is far too fast. We also want some damping for Gazebo -->
        <limit effort="100" lower="0.0495" upper="1.2218" velocity="1.23" />
        <dynamics damping="1" friction="0.1" />
    </joint>
    <joint name="s_model_finger_2_joint_2" type="revolute">
        <parent link="s_model_finger_2_link_1" />
        <child link="s_model_finger_2_link_2" />
        <axis xyz="0 0 1" />
        <origin rpy="0 0 -0.52" xyz="0.050 -.028 0" />
        <limit effort="100" lower="0.0" upper="1.5708" velocity="1.24" />
        <dynamics damping="1" friction="0.1" />
    </joint>
    <joint name="s_model_finger_2_joint_3" type="revolute">
        <parent link="s_model_finger_2_link_2" />
        <child link="s_model_finger_2_link_3" />
        <axis xyz="0 0 1" />
        <origin rpy="0 0 0" xyz="0.039 0 0" />
        <limit effort="100" lower="-1.2217" upper="-0.0523" velocity="1.25" />
        <dynamics damping="1" friction="0.1" />
    </joint>
    <!-- end of joint list -->
    <!-- link list -->
    <link name="s_model_finger_middle_link_0">
        <visual>
            <origin rpy="0 0 0" xyz="0.020 0 0" />
            <geometry>
                <mesh filename="package://robotiq_3f_gripper_visualization/meshes/robotiq-3f-gripper_articulated/visual/link_0.dae" />
            </geometry>
            <material name="gray">
                <color rgba="0.2 0.2 0.2 1" />
            </material>
        </visual>
        <collision>
            <origin rpy="0 0 0" xyz="0.020 0 0" />
            <geometry>
                <mesh filename="package://robotiq_3f_gripper_visualization/meshes/robotiq-3f-gripper_articulated/collision/link_0.STL" />
            </geometry>
            <material name="yellow">
                <color rgba="0 1 1 1" />
            </material>
        </collision>
        <inertial>
            <origin rpy="0 0 0" xyz="0 0 0" />
            <mass value="0.05" />
            <inertia ixx="0.01" ixy="-0.00002" ixz="0.00001" iyy="0.0008" iyz="0" izz="0.001" />
        </inertial>
    </link>
    <link name="s_model_finger_middle_link_1">
        <visual>
            <origin rpy="0 0 -0.52" xyz="0.050 -.028 0" />
            <geometry>
                <mesh filename="package://robotiq_3f_gripper_visualization/meshes/robotiq-3f-gripper_articulated/visual/link_1.dae" />
            </geometry>
            <material name="gray" />
        </visual>
        <collision>
            <origin rpy="0 0 -0.52" xyz="0.050 -.028 0" />
            <geometry>
                <mesh filename="package://robotiq_3f_gripper_visualization/meshes/robotiq-3f-gripper_articulated/collision/link_1.STL" />
            </geometry>
            <material name="yellow" />
        </collision>
        <inertial>
            <origin rpy="0 0 0" xyz="0 0 0" />
            <mass value="0.15" />
            <inertia ixx="0.001859" ixy="-0.000376" ixz="0.000028" iyy="0.012756" iyz="0" izz="0.0024" />
        </inertial>
    </link>
    <link name="s_model_finger_middle_link_2">
        <!--
			NOTE: This link has an offset in the z-direction based on the models that were
			used to generate grap-it poses.  With the offset below the model appears visually
			correct, but it is suspect.
			-->
        <visual>
            <origin rpy="0 0 0" xyz="0.039 0 0.0075" />
            <geometry>
                <mesh filename="package://robotiq_3f_gripper_visualization/meshes/robotiq-3f-gripper_articulated/visual/link_2.dae" />
            </geometry>
            <material name="gray" />
        </visual>
        <collision>
            <origin rpy="0 0 0" xyz="0.039 0 0.0075" />
            <geometry>
                <mesh filename="package://robotiq_3f_gripper_visualization/meshes/robotiq-3f-gripper_articulated/collision/link_2.STL" />
            </geometry>
            <material name="yellow" />
        </collision>
        <inertial>
            <origin rpy="0 0 0" xyz="0 0 0" />
            <mass value="0.15" />
            <inertia ixx="0.001859" ixy="-0.000376" ixz="0.000028" iyy="0.012756" iyz="0" izz="0.0024" />
        </inertial>
    </link>
    <link name="s_model_finger_middle_link_3">
        <visual>
            <origin rpy="0 0 0.52" xyz="0 0 0" />
            <geometry>
                <mesh filename="package://robotiq_3f_gripper_visualization/meshes/robotiq-3f-gripper_articulated/visual/link_3.dae" />
            </geometry>
            <material name="gray" />
        </visual>
        <collision>
            <origin rpy="0 0 0.52" xyz="0 0 0" />
            <geometry>
                <mesh filename="package://robotiq_3f_gripper_visualization/meshes/robotiq-3f-gripper_articulated/collision/link_3.STL" />
            </geometry>
            <material name="yellow" />
        </collision>
        <inertial>
            <origin rpy="0 0 0" xyz="0 0 0" />
            <mass value="0.05" />
            <inertia ixx="0.001239" ixy="-0.000251" ixz="0.000019" iyy="0.00085" iyz="0" izz="0.001632" />
        </inertial>
    </link>
    <!-- end of link list -->
    <!-- joint list -->
    <joint name="s_model_finger_middle_joint_1" type="revolute">
        <parent link="s_model_finger_middle_link_0" />
        <child link="s_model_finger_middle_link_1" />
        <axis xyz="0 0 1" />
        <origin rpy="0 0 0" xyz="0.020 0 0" />
        <!-- fnh: velocity=100 is far too fast. We also want some damping for Gazebo -->
        <limit effort="100" lower="0.0495" upper="1.2218" velocity="1.23" />
        <dynamics damping="1" friction="0.1" />
    </joint>
    <joint name="s_model_finger_middle_joint_2" type="revolute">
        <parent link="s_model_finger_middle_link_1" />
        <child link="s_model_finger_middle_link_2" />
        <axis xyz="0 0 1" />
        <origin rpy="0 0 -0.52" xyz="0.050 -.028 0" />
        <limit effort="100" lower="0.0" upper="1.5708" velocity="1.24" />
        <dynamics damping="1" friction="0.1" />
    </joint>
    <joint name="s_model_finger_middle_joint_3" type="revolute">
        <parent link="s_model_finger_middle_link_2" />
        <child link="s_model_finger_middle_link_3" />
        <axis xyz="0 0 1" />
        <origin rpy="0 0 0" xyz="0.039 0 0" />
        <limit effort="100" lower="-1.2217" upper="-0.0523" velocity="1.25" />
        <dynamics damping="1" friction="0.1" />
    </joint>
    <!-- end of joint list -->
    <!-- link list -->
    <link name="s_model_palm">
        <visual>
            <geometry>
                <mesh filename="package://robotiq_3f_gripper_visualization/meshes/robotiq-3f-gripper_articulated/visual/palm.dae" />
            </geometry>
            <material name="gray">
                <color rgba="0.2 0.2 0.2 1" />
            </material>
        </visual>
        <collision>
            <geometry>
                <mesh filename="package://robotiq_3f_gripper_visualization/meshes/robotiq-3f-gripper_articulated/collision/palm_with_finger_cutouts.stl" />
            </geometry>
            <material name="yellow">
                <color rgba="0 1 1 1" />
            </material>
        </collision>
        <inertial>
            <mass value="0.1" />
            <origin xyz="0 0 0" rpy="0 0 0" />
            <inertia ixx="0.03" iyy="0.03" izz="0.03" ixy="0.0" ixz="0.0" iyz="0.0" />
        </inertial>
    </link>
    <link name="s_model_tool0" />
    <inertial>
        <origin rpy="0 0 0" xyz="0 0 0" />
        <mass value="1.3" />
        <inertia ixx="0.006012" ixy="0.000079" ixz="-0.00024" iyy="0.012892" iyz="0" izz="0.002435" />
    </inertial>
    <!-- end of link list -->
    <!-- joint list -->
    <joint name="s_model_palm_finger_1_joint" type="revolute">
        <parent link="s_model_palm" />
        <child link="s_model_finger_1_link_0" />
        <axis xyz="0 1 0" />
        <origin rpy="0 3.1416 -1.57" xyz="-0.0455 0.0214 0.036" />
        <limit effort="100" lower="-0.1784" upper="0.192" velocity="1.23" />
        <dynamics damping="1.0" friction="0.1" />
    </joint>
    <joint name="s_model_palm_finger_2_joint" type="revolute">
        <parent link="s_model_palm" />
        <child link="s_model_finger_2_link_0" />
        <axis xyz="0 1 0" />
        <origin rpy="0 3.1416 -1.57" xyz="-0.0455 0.0214 -0.036" />
        <limit effort="100" lower="-0.192" upper="0.1784" velocity="1.23" />
        <dynamics damping="1.0" friction="0.1" />
    </joint>
    <joint name="s_model_palm_finger_middle_joint" type="fixed">
        <parent link="s_model_palm" />
        <child link="s_model_finger_middle_link_0" />
        <axis xyz="0 0 1" />
        <origin rpy="0 0 1.57" xyz="0.0455 0.0214 0" />
    </joint>
    <joint name="s_model_palm_tool0" type="fixed">
        <parent link="s_model_palm" />
        <child link="s_model_tool0" />
        <origin rpy="0 0 1.5707" xyz="0.0 0.0875 0.0" />
    </joint>
    <!-- end of joint list -->
    <joint name="gripper_joint" type="fixed">
        <parent link="tool0" />
        <child link="s_model_palm" />
        <origin rpy="0.0 3.141592653589793 -1.5707963267948966" xyz="0.057 0.0 0.0" />
    </joint>
    <!-- gripper plugs  -->
    <link name="plug_collision_model_link_1">
        <!-- TODO values for inertial are not correct -->
        <inertial>
            <mass value="0.2" />
            <origin xyz="0.0 0.0 0.0" rpy="0 0 0" />
            <inertia ixx="0.002708332" ixy="0.0" ixz="0.0" iyy="0.000708333" iyz="0.0" izz="0.003333332" />
        </inertial>
        <visual>
            <origin rpy="0.0 0.0 0.0" xyz="0.08 -0.05 0.0" />
            <geometry>
                <box size="0.08 0.10 0.075" />
            </geometry>
            <material name="plug_collision_model_link1_mat">
                <color rgba="0.7 0.7 0.7 0.3" />
            </material>
        </visual>
        <collision>
            <origin rpy="0.0 0.0 0.0" xyz="0.08 -0.05 0.0" />
            <geometry>
                <box size="0.08 0.10 0.075" />
            </geometry>
        </collision>
    </link>
    <joint name="plug_collision_model_link_1_joint" type="fixed">
        <origin rpy="0.0 0.0 0.0" xyz="0.0 0.0 0.0" />
        <child link="plug_collision_model_link_1" />
        <parent link="ur5_ee_link" />
    </joint>
    <!-- force torque plug -->
    <link name="plug_collision_model_link_2">
        <!-- TODO values for inertial are not correct -->
        <inertial>
            <mass value="0.2" />
            <origin xyz="0.0 0.0 0.0" rpy="0 0 0" />
            <inertia ixx="0.002708332" ixy="0.0" ixz="0.0" iyy="0.000708333" iyz="0.0" izz="0.003333332" />
        </inertial>
        <visual>
            <origin rpy="0.0 0.0 0.0" xyz="0.025 -0.025 0.06" />
            <geometry>
                <box size="0.03 0.09 0.12" />
            </geometry>
            <material name="plug_collision_model_link2_mat">
                <color rgba="0.7 0.7 0.7 0.3" />
            </material>
        </visual>
        <collision>
            <origin rpy="0.0 0.0 0.0" xyz="0.025 -0.025 0.06" />
            <geometry>
                <box size="0.03 0.09 0.12" />
            </geometry>
        </collision>
    </link>
    <joint name="plug_collision_model_link_2_joint" type="fixed">
        <origin rpy="0.0 0.0 0.0" xyz="0.0 0.0 0.0" />
        <child link="plug_collision_model_link_2" />
        <parent link="ur5_ee_link" />
    </joint>
    <!-- usb hub -->
    <link name="plug_collision_model_link_3">
        <!-- TODO values for inertial are not correct -->
        <inertial>
            <mass value="0.2" />
            <origin xyz="0.0 0.0 0.0" rpy="0 0 0" />
            <inertia ixx="0.002708332" ixy="0.0" ixz="0.0" iyy="0.000708333" iyz="0.0" izz="0.003333332" />
        </inertial>
        <visual>
            <origin rpy="0.0 0.0 0.0" xyz="0.025 -0.0 0.06" />
            <geometry>
                <box size="0.08 0.15 0.13" />
            </geometry>
            <material name="plug_collision_model_link3_mat">
                <color rgba="0.7 0.7 0.7 0.3" />
            </material>
        </visual>
        <collision>
            <origin rpy="0.0 0.0 0.0" xyz="0.025 -0.0 0.06" />
            <geometry>
                <box size="0.08 0.15 0.13" />
            </geometry>
        </collision>
    </link>
    <joint name="plug_collision_model_link_3_joint" type="fixed">
        <origin rpy="0.0 0.0 0.0" xyz="0.0 0.0 0.0" />
        <child link="plug_collision_model_link_3" />
        <parent link="ur5_ee_link" />
    </joint>
    <!-- we want Gazebo to publish joint_states for all configured joints -->
    <gazebo>
        <plugin filename="libgazebo_ros_control.so" name="tams_ur5_gazebo_ros_control">
            <robotNamespace>/</robotNamespace>
            <robotSimType>gazebo_ros_control/DefaultRobotHWSim</robotSimType>
            <legacyModeNS>true</legacyModeNS>
            <updateRate>1000.0</updateRate>
        </plugin>
    </gazebo>
    <transmission name="ur5_shoulder_pan_joint_transmission">
        <type>transmission_interface/SimpleTransmission</type>
        <actuator name="ur5_shoulder_pan_joint_motor">
            <mechanicalReduction>1.0</mechanicalReduction>
            <hardwareInterface>hardware_interface/EffortJointInterface</hardwareInterface>
        </actuator>
        <joint name="ur5_shoulder_pan_joint">
            <hardwareInterface>hardware_interface/EffortJointInterface</hardwareInterface>
        </joint>
    </transmission>
    <transmission name="ur5_shoulder_lift_joint_transmission">
        <type>transmission_interface/SimpleTransmission</type>
        <actuator name="ur5_shoulder_lift_joint_motor">
            <mechanicalReduction>1.0</mechanicalReduction>
            <hardwareInterface>hardware_interface/EffortJointInterface</hardwareInterface>
        </actuator>
        <joint name="ur5_shoulder_lift_joint">
            <hardwareInterface>hardware_interface/EffortJointInterface</hardwareInterface>
        </joint>
    </transmission>
    <transmission name="ur5_elbow_joint_transmission">
        <type>transmission_interface/SimpleTransmission</type>
        <actuator name="ur5_elbow_joint_motor">
            <mechanicalReduction>1.0</mechanicalReduction>
            <hardwareInterface>hardware_interface/EffortJointInterface</hardwareInterface>
        </actuator>
        <joint name="ur5_elbow_joint">
            <hardwareInterface>hardware_interface/EffortJointInterface</hardwareInterface>
        </joint>
    </transmission>
    <transmission name="ur5_wrist_1_joint_transmission">
        <type>transmission_interface/SimpleTransmission</type>
        <actuator name="ur5_wrist_1_joint_motor">
            <mechanicalReduction>1.0</mechanicalReduction>
            <hardwareInterface>hardware_interface/EffortJointInterface</hardwareInterface>
        </actuator>
        <joint name="ur5_wrist_1_joint">
            <hardwareInterface>hardware_interface/EffortJointInterface</hardwareInterface>
        </joint>
    </transmission>
    <transmission name="ur5_wrist_2_joint_transmission">
        <type>transmission_interface/SimpleTransmission</type>
        <actuator name="ur5_wrist_2_joint_motor">
            <mechanicalReduction>1.0</mechanicalReduction>
            <hardwareInterface>hardware_interface/EffortJointInterface</hardwareInterface>
        </actuator>
        <joint name="ur5_wrist_2_joint">
            <hardwareInterface>hardware_interface/EffortJointInterface</hardwareInterface>
        </joint>
    </transmission>
    <transmission name="ur5_wrist_3_joint_transmission">
        <type>transmission_interface/SimpleTransmission</type>
        <actuator name="ur5_wrist_3_joint_motor">
            <mechanicalReduction>1.0</mechanicalReduction>
            <hardwareInterface>hardware_interface/EffortJointInterface</hardwareInterface>
        </actuator>
        <joint name="ur5_wrist_3_joint">
            <hardwareInterface>hardware_interface/EffortJointInterface</hardwareInterface>
        </joint>
    </transmission>
    <transmission name="s_model_palm_finger_1_joint_transmission">
        <type>transmission_interface/SimpleTransmission</type>
        <actuator name="s_model_palm_finger_1_joint_motor">
            <mechanicalReduction>1.0</mechanicalReduction>
            <hardwareInterface>hardware_interface/EffortJointInterface</hardwareInterface>
        </actuator>
        <joint name="s_model_palm_finger_1_joint">
            <hardwareInterface>hardware_interface/EffortJointInterface</hardwareInterface>
        </joint>
    </transmission>
    <transmission name="s_model_finger_1_joint_1_transmission">
        <type>transmission_interface/SimpleTransmission</type>
        <actuator name="s_model_finger_1_joint_1_motor">
            <mechanicalReduction>1.0</mechanicalReduction>
            <hardwareInterface>hardware_interface/EffortJointInterface</hardwareInterface>
        </actuator>
        <joint name="s_model_finger_1_joint_1">
            <hardwareInterface>hardware_interface/EffortJointInterface</hardwareInterface>
        </joint>
    </transmission>
    <transmission name="s_model_finger_1_joint_2_transmission">
        <type>transmission_interface/SimpleTransmission</type>
        <actuator name="s_model_finger_1_joint_2_motor">
            <mechanicalReduction>1.0</mechanicalReduction>
            <hardwareInterface>hardware_interface/EffortJointInterface</hardwareInterface>
        </actuator>
        <joint name="s_model_finger_1_joint_2">
            <hardwareInterface>hardware_interface/EffortJointInterface</hardwareInterface>
        </joint>
    </transmission>
    <transmission name="s_model_finger_1_joint_3_transmission">
        <type>transmission_interface/SimpleTransmission</type>
        <actuator name="s_model_finger_1_joint_3_motor">
            <mechanicalReduction>1.0</mechanicalReduction>
            <hardwareInterface>hardware_interface/EffortJointInterface</hardwareInterface>
        </actuator>
        <joint name="s_model_finger_1_joint_3">
            <hardwareInterface>hardware_interface/EffortJointInterface</hardwareInterface>
        </joint>
    </transmission>
    <transmission name="s_model_palm_finger_2_joint_transmission">
        <type>transmission_interface/SimpleTransmission</type>
        <actuator name="s_model_palm_finger_2_joint_motor">
            <mechanicalReduction>1.0</mechanicalReduction>
            <hardwareInterface>hardware_interface/EffortJointInterface</hardwareInterface>
        </actuator>
        <joint name="s_model_palm_finger_2_joint">
            <hardwareInterface>hardware_interface/EffortJointInterface</hardwareInterface>
        </joint>
    </transmission>
    <transmission name="s_model_finger_2_joint_1_transmission">
        <type>transmission_interface/SimpleTransmission</type>
        <actuator name="s_model_finger_2_joint_1_motor">
            <mechanicalReduction>1.0</mechanicalReduction>
            <hardwareInterface>hardware_interface/EffortJointInterface</hardwareInterface>
        </actuator>
        <joint name="s_model_finger_2_joint_1">
            <hardwareInterface>hardware_interface/EffortJointInterface</hardwareInterface>
        </joint>
    </transmission>
    <transmission name="s_model_finger_2_joint_2_transmission">
        <type>transmission_interface/SimpleTransmission</type>
        <actuator name="s_model_finger_2_joint_2_motor">
            <mechanicalReduction>1.0</mechanicalReduction>
            <hardwareInterface>hardware_interface/EffortJointInterface</hardwareInterface>
        </actuator>
        <joint name="s_model_finger_2_joint_2">
            <hardwareInterface>hardware_interface/EffortJointInterface</hardwareInterface>
        </joint>
    </transmission>
    <transmission name="s_model_finger_2_joint_3_transmission">
        <type>transmission_interface/SimpleTransmission</type>
        <actuator name="s_model_finger_2_joint_3_motor">
            <mechanicalReduction>1.0</mechanicalReduction>
            <hardwareInterface>hardware_interface/EffortJointInterface</hardwareInterface>
        </actuator>
        <joint name="s_model_finger_2_joint_3">
            <hardwareInterface>hardware_interface/EffortJointInterface</hardwareInterface>
        </joint>
    </transmission>
    <transmission name="s_model_finger_middle_joint_1_transmission">
        <type>transmission_interface/SimpleTransmission</type>
        <actuator name="s_model_finger_middle_joint_1_motor">
            <mechanicalReduction>1.0</mechanicalReduction>
            <hardwareInterface>hardware_interface/EffortJointInterface</hardwareInterface>
        </actuator>
        <joint name="s_model_finger_middle_joint_1">
            <hardwareInterface>hardware_interface/EffortJointInterface</hardwareInterface>
        </joint>
    </transmission>
    <transmission name="s_model_finger_middle_joint_2_transmission">
        <type>transmission_interface/SimpleTransmission</type>
        <actuator name="s_model_finger_middle_joint_2_motor">
            <mechanicalReduction>1.0</mechanicalReduction>
            <hardwareInterface>hardware_interface/EffortJointInterface</hardwareInterface>
        </actuator>
        <joint name="s_model_finger_middle_joint_2">
            <hardwareInterface>hardware_interface/EffortJointInterface</hardwareInterface>
        </joint>
    </transmission>
    <transmission name="s_model_finger_middle_joint_3_transmission">
        <type>transmission_interface/SimpleTransmission</type>
        <actuator name="s_model_finger_middle_joint_3_motor">
            <mechanicalReduction>1.0</mechanicalReduction>
            <hardwareInterface>hardware_interface/EffortJointInterface</hardwareInterface>
        </actuator>
        <joint name="s_model_finger_middle_joint_3">
            <hardwareInterface>hardware_interface/EffortJointInterface</hardwareInterface>
        </joint>
    </transmission>
    <link name="world" />
    <joint name="world_floor_joint" type="fixed">
        <parent link="world" />
        <child link="floor" />
        <origin rpy="0.0 0.0 0.0" xyz="0.0 0.0 0.0" />
    </joint>
    <link name="map" />
    <joint name="map_world" type="fixed">
        <parent link="world" />
        <child link="map" />
        <origin rpy="0.0 0.0 -0.32" xyz="0.9 1.3 0.0" />
    </joint>
    <joint name="wall_ur5_joint" type="fixed">
        <parent link="ur5_mount" />
        <child link="ur5_base_link" />
        <origin rpy="0.0 0.0 1.5707963267948966" xyz="0 0 0.003" />
    </joint>
    <joint name="world_marimba_joint" type="fixed">
        <parent link="world" />
        <child link="marimba" />
        <origin rpy="0.0 0.0 3.141592653589793" xyz="1.25 0.8 0.80" />
    </joint>
    <link name="mallet_base_link">
        <visual>
            <origin rpy="-1.5707963267948966 0.0 0.0" xyz="-0.0315 -0.0342 0.11" />
            <geometry>
                <mesh filename="package://marimbabot_description/mesh/two_mallet_base_element.stl" scale="0.001 0.001 0.001" />
            </geometry>
            <material name="mallet_holder_white">
                <color rgba="1.0 1.0 1.0 1.0" />
            </material>
        </visual>
        <collision>
            <origin rpy="0.0 0.0 0.0" xyz="0.0 0.0 0.055" />
            <geometry>
                <box size="0.077 0.0804 0.11" />
            </geometry>
        </collision>
        <inertial>
            <mass value="0.1" />
            <origin xyz="0 0 0" rpy="0 0 0" />
            <inertia ixx="0.03" iyy="0.03" izz="0.03" ixy="0.0" ixz="0.0" iyz="0.0" />
        </inertial>
    </link>
    <link name="mallet_servo_box">
        <visual>
            <origin rpy="-1.5707963267948966 0.0 0.0" xyz="-0.01 -0.0342 0.0233" />
            <geometry>
                <mesh filename="package://marimbabot_description/mesh/two_mallet_servo_element.stl" scale="0.001 0.001 0.001" />
            </geometry>
            <material name="mallet_holder_white">
                <color rgba="1.0 1.0 1.0 1.0" />
            </material>
        </visual>
    </link>
    <link name="mallet_base_box_1">
        <visual>
            <origin rpy="-1.5707963267948966 -1.5707963267948966 0.0" xyz="0.0 0.0 0.045" />
            <geometry>
                <mesh filename="package://marimbabot_description/mesh/mallet_double_flex.stl" scale="0.001 0.001 0.001" />
            </geometry>
            <material name="mallet_holder_white">
                <color rgba="1.0 1.0 1.0 1.0" />
            </material>
        </visual>
        <collision>
            <origin rpy="0.0 0.0 0.0" xyz="0.0 0.0 0.045" />
            <geometry>
                <box size="0.033 0.09 0.09" />
            </geometry>
        </collision>
        <inertial>
            <mass value="0.1" />
            <origin xyz="0 0 0" rpy="0 0 0" />
            <inertia ixx="0.03" iyy="0.03" izz="0.03" ixy="0.0" ixz="0.0" iyz="0.0" />
        </inertial>
    </link>
    <link name="mallet_base_box_2">
        <visual>
            <origin rpy="-1.5707963267948966 -1.5707963267948966 3.141592653589793" xyz="0.0 0.0 0.045" />
            <geometry>
                <mesh filename="package://marimbabot_description/mesh/mallet_double_flex.stl" scale="0.001 0.001 0.001" />
            </geometry>
            <material name="mallet_holder_white">
                <color rgba="1.0 1.0 1.0 1.0" />
            </material>
        </visual>
        <collision>
            <origin rpy="0.0 0.0 0.0" xyz="0.0 0.0 0.045" />
            <geometry>
                <box size="0.033 0.09 0.09" />
            </geometry>
        </collision>
        <inertial>
            <mass value="0.1" />
            <origin xyz="0 0 0" rpy="0 0 0" />
            <inertia ixx="0.03" iyy="0.03" izz="0.03" ixy="0.0" ixz="0.0" iyz="0.0" />
        </inertial>
    </link>
    <link name="mallet_neck_1">
        <collision>
            <origin rpy="0.0 0.0 0.0" xyz="0.0 0.0 0.1875" />
            <geometry>
                <cylinder length="0.375" radius="0.0042" />
            </geometry>
        </collision>
        <inertial>
            <mass value="0.1" />
            <origin xyz="0 0 0" rpy="0 0 0" />
            <inertia ixx="0.03" iyy="0.03" izz="0.03" ixy="0.0" ixz="0.0" iyz="0.0" />
        </inertial>
    </link>
    <link name="mallet_neck_2">
        <collision>
            <origin rpy="0.0 0.0 0.0" xyz="0.0 0.0 0.1875" />
            <geometry>
                <cylinder length="0.375" radius="0.0042" />
            </geometry>
        </collision>
        <inertial>
            <mass value="0.1" />
            <origin xyz="0 0 0" rpy="0 0 0" />
            <inertia ixx="0.03" iyy="0.03" izz="0.03" ixy="0.0" ixz="0.0" iyz="0.0" />
        </inertial>
    </link>
    <link name="mallet_head_1">
        <collision>
            <origin rpy="0.0 0.0 0.0" xyz="0.0 0.0 0.0" />
            <geometry>
                <sphere radius="0.018375" />
            </geometry>
        </collision>
        <inertial>
            <mass value="0.1" />
            <origin xyz="0 0 0" rpy="0 0 0" />
            <inertia ixx="0.03" iyy="0.03" izz="0.03" ixy="0.0" ixz="0.0" iyz="0.0" />
        </inertial>
    </link>
    <link name="mallet_head_2">
        <collision>
            <origin rpy="0.0 0.0 0.0" xyz="0.0 0.0 0.0" />
            <geometry>
                <sphere radius="0.018375" />
            </geometry>
        </collision>
        <inertial>
            <mass value="0.1" />
            <origin xyz="0 0 0" rpy="0 0 0" />
            <inertia ixx="0.03" iyy="0.03" izz="0.03" ixy="0.0" ixz="0.0" iyz="0.0" />
        </inertial>
    </link>
    <joint name="mallet_base_link_group_1" type="fixed">
        <parent link="mallet_base_link" />
        <child link="mallet_base_box_1" />
        <origin xyz="0.021 0.0038 0.12179999999999999" />
    </joint>
    <joint name="mallet_finger" type="revolute">
        <parent link="mallet_base_link" />
        <child link="mallet_servo_box" />
        <origin xyz="-0.0215 0.0 0.0868" />
        <limit effort="1.0" lower="0.0" upper="0.801" velocity="7.0" />
        <axis xyz="0.0 -1.0 0.0" />
    </joint>
    <joint name="mallet_group_1_start_link" type="fixed">
        <parent link="mallet_base_box_1" />
        <child link="mallet_neck_1" />
        <origin xyz="0.0 0.0 0.015" />
    </joint>
    <joint name="mallet_group_1_2nd_link" type="fixed">
        <parent link="mallet_neck_1" />
        <child link="mallet_head_1" />
        <origin xyz="0.0 0.0 0.38337499999999997" />
    </joint>
    <joint name="mallet_group_2_start_link" type="fixed">
        <parent link="mallet_servo_box" />
        <child link="mallet_base_box_2" />
        <origin xyz="0.0075 0.0038 0.0351" />
    </joint>
    <joint name="mallet_group_2_2nd_link" type="fixed">
        <parent link="mallet_base_box_2" />
        <child link="mallet_neck_2" />
        <origin xyz="0.0 0.0 0.015" />
    </joint>
    <joint name="mallet_group_2_3rd_link" type="fixed">
        <parent link="mallet_neck_2" />
        <child link="mallet_head_2" />
        <origin xyz="0.0 0.0 0.38337499999999997" />
    </joint>
    <joint name="end_mallet" type="fixed">
        <parent link="s_model_palm" />
        <child link="mallet_base_link" />
        <origin rpy="0.0 0.0 3.141592653589793" xyz="0.0 0.091 -0.045" />
    </joint>
    <transmission name="trans_mallet_finger">
        <type>transmission_interface/SimpleTransmission</type>
        <joint name="mallet_finger">
            <hardwareInterface>hardware_interface/EffortJointInterface</hardwareInterface>
        </joint>
        <actuator name="mallet_finger_motor">
            <hardwareInterface>hardware_interface/EffortJointInterface</hardwareInterface>
            <mechanicalReduction>1</mechanicalReduction>
        </actuator>
    </transmission>
</robot>

